Workbook

Sheet Summary
A1: Type | B1: Category | C1: Brand | D1: 202401 | E1: 202402 | F1: 202403 | G1: 202404 | H1: 202405 | I1: 202406 | J1: 202407 | K1: 202408 | L1: 202409 | M1: 202410 | N1: 202411 | O1: 202412 | P1: 202501 | Q1: 202502 | R1: 202503 | S1: 202504 | T1: 202505 | U1: 202506 | V1: 202507 | W1: 202508 | X1: 202509 | Y1: 202510 | Z1: 202511 | AA1: 202512 | AB1: 202601 | AC1: 202602 | AD1: 202603 | AE1: 202604 | AF1: 202605 | AG1: 202606 | AJ1: CM | AK1: FYTD | AL1: CYTD | AM1: JAS | AN1: OND | AO1: JFM | AP1: AMJ | AQ1: 1H | AR1: 2H | AS1: FY
A2: Offtake | B2: Total | C2: Total | D2: =SUM(D3,D8,D14,D18,D24,D27,D34) -> 26.875749 | E2: =SUM(E3,E8,E14,E18,E24,E27,E34) -> 31.613833 | F2: =SUM(F3,F8,F14,F18,F24,F27,F34) -> 25.597481 | G2: =SUM(G3,G8,G14,G18,G24,G27,G34) -> 25.517446 | H2: =SUM(H3,H8,H14,H18,H24,H27,H34) -> 30.36131 | I2: =SUM(I3,I8,I14,I18,I24,I27,I34) -> 25.890439 | J2: =SUM(J3,J8,J14,J18,J24,J27,J34) -> 25.464544 | K2: =SUM(K3,K8,K14,K18,K24,K27,K34) -> 26.673421 | ... AG2: =SUM(AG3,AG8,AG14,AG18,AG24,AG27,AG34) -> 41.653471 | AJ2: =IFERROR(AE2/S2*100,"NA") -> 118.64449 | AK2: =IFERROR(SUM(V2:AE2)/SUM(J2:S2)*100,"NA") -> 119.00053 | AL2: =IFERROR(SUM(AB2:AE2)/SUM(P2:S2)*100,"NA") -> 108.30305 | AM2: =IFERROR(SUM(V2:X2)/SUM(J2:L2)*100,"NA") -> 117.15717 | AN2: =IFERROR(SUM(Y2:AA2)/SUM(M2:O2)*100,"NA") -> 133.69033 | AO2: =IFERROR(SUM(AB2:AD2)/SUM(P2:R2)*100,"NA") -> 104.81625 | AP2: =IFERROR(SUM(AE2:AG2)/SUM(S2:U2)*100,"NA") -> 107.67803 | AQ2: =IFERROR(SUM(V2:AA2)/SUM(J2:O2)*100,"NA") -> 126.33812 | AR2: =IFERROR(SUM(AB2:AG2)/SUM(P2:U2)*100,"NA") -> 106.37127 | AS2: =IFERROR(SUM(V2:AG2)/SUM(J2:U2)*100,"NA") -> 115.7746
A3: Offtake | B3: Hair | C3: Total | D3: =Hair!F3 -> 7.2976789 | E3: =Hair!G3 -> 9.0880794 | F3: =Hair!H3 -> 7.547991 | G3: =Hair!I3 -> 6.8362572 | H3: =Hair!J3 -> 7.7994483 | I3: =Hair!K3 -> 7.7877277 | J3: =Hair!L3 -> 7.0275254 | K3: =Hair!M3 -> 7.4311767 | ... AG3: =Hair!AI3 -> 12.4325 | AJ3: =IFERROR(AE3/S3*100,"NA") -> 113.80084 | AK3: =IFERROR(SUM(V3:AE3)/SUM(J3:S3)*100,"NA") -> 129.86905 | AL3: =IFERROR(SUM(AB3:AE3)/SUM(P3:S3)*100,"NA") -> 113.9543 | AM3: =IFERROR(SUM(V3:X3)/SUM(J3:L3)*100,"NA") -> 134.99625 | AN3: =IFERROR(SUM(Y3:AA3)/SUM(M3:O3)*100,"NA") -> 146.53094 | AO3: =IFERROR(SUM(AB3:AD3)/SUM(P3:R3)*100,"NA") -> 114.01157 | AP3: =IFERROR(SUM(AE3:AG3)/SUM(S3:U3)*100,"NA") -> 106.56187 | AQ3: =IFERROR(SUM(V3:AA3)/SUM(J3:O3)*100,"NA") -> 141.69283 | AR3: =IFERROR(SUM(AB3:AG3)/SUM(P3:U3)*100,"NA") -> 109.91866 | AS3: =IFERROR(SUM(V3:AG3)/SUM(J3:U3)*100,"NA") -> 124.35693
B4: HNS | C4: HNS | D4: =Hair!F6 -> 1.1561017 | E4: =Hair!G6 -> 1.520378 | F4: =Hair!H6 -> 1.4297258 | G4: =Hair!I6 -> 1.1546554 | H4: =Hair!J6 -> 1.4983956 | I4: =Hair!K6 -> 1.8250481 | J4: =Hair!L6 -> 1.485706 | K4: =Hair!M6 -> 1.6607624 | ... AG4: =Hair!AI6 -> 2.47 | AJ4: =IFERROR(AE4/S4*100,"NA") -> 75.790763 | AK4: =IFERROR(SUM(V4:AE4)/SUM(J4:S4)*100,"NA") -> 116.09933 | AL4: =IFERROR(SUM(AB4:AE4)/SUM(P4:S4)*100,"NA") -> 97.696861 | AM4: =IFERROR(SUM(V4:X4)/SUM(J4:L4)*100,"NA") -> 126.34213 | AN4: =IFERROR(SUM(Y4:AA4)/SUM(M4:O4)*100,"NA") -> 133.71547 | AO4: =IFERROR(SUM(AB4:AD4)/SUM(P4:R4)*100,"NA") -> 111.11733 | AP4: =IFERROR(SUM(AE4:AG4)/SUM(S4:U4)*100,"NA") -> 86.875097 | AQ4: =IFERROR(SUM(V4:AA4)/SUM(J4:O4)*100,"NA") -> 130.18317 | AR4: =IFERROR(SUM(AB4:AG4)/SUM(P4:U4)*100,"NA") -> 95.846749 | AS4: =IFERROR(SUM(V4:AG4)/SUM(J4:U4)*100,"NA") -> 110.89104
B5: PTN | C5: PTN | D5: =Hair!F42 -> 3.6296792 | E5: =Hair!G42 -> 3.4605706 | F5: =Hair!H42 -> 3.1276284 | G5: =Hair!I42 -> 3.1032522 | H5: =Hair!J42 -> 2.6596319 | I5: =Hair!K42 -> 2.6082213 | J5: =Hair!L42 -> 2.9359616 | K5: =Hair!M42 -> 2.5585862 | ... AG5: =Hair!AI42 -> 4.9025 | AJ5: =IFERROR(AE5/S5*100,"NA") -> 163.65621 | AK5: =IFERROR(SUM(V5:AE5)/SUM(J5:S5)*100,"NA") -> 134.36048 | AL5: =IFERROR(SUM(AB5:AE5)/SUM(P5:S5)*100,"NA") -> 138.00142 | AM5: =IFERROR(SUM(V5:X5)/SUM(J5:L5)*100,"NA") -> 131.10558 | AN5: =IFERROR(SUM(Y5:AA5)/SUM(M5:O5)*100,"NA") -> 132.67151 | AO5: =IFERROR(SUM(AB5:AD5)/SUM(P5:R5)*100,"NA") -> 130.08768 | AP5: =IFERROR(SUM(AE5:AG5)/SUM(S5:U5)*100,"NA") -> 122.03314 | AQ5: =IFERROR(SUM(V5:AA5)/SUM(J5:O5)*100,"NA") -> 132.05531 | AR5: =IFERROR(SUM(AB5:AG5)/SUM(P5:U5)*100,"NA") -> 125.57465 | AS5: =IFERROR(SUM(V5:AG5)/SUM(J5:U5)*100,"NA") -> 128.66
B6: Pert | C6: Pert | D6: =Hair!F84 -> 0.386891 | E6: =Hair!G84 -> 0.5931387 | F6: =Hair!H84 -> 0.5326613 | G6: =Hair!I84 -> 0.5880434 | H6: =Hair!J84 -> 0.6140804 | I6: =Hair!K84 -> 0.396426 | J6: =Hair!L84 -> 0.5345098 | K6: =Hair!M84 -> 0.6603507 | ... AG6: =Hair!AI84 -> 0.46 | AJ6: =IFERROR(AE6/S6*100,"NA") -> 79.509757 | AK6: =IFERROR(SUM(V6:AE6)/SUM(J6:S6)*100,"NA") -> 76.22448 | AL6: =IFERROR(SUM(AB6:AE6)/SUM(P6:S6)*100,"NA") -> 67.034409 | AM6: =IFERROR(SUM(V6:X6)/SUM(J6:L6)*100,"NA") -> 91.530544 | AN6: =IFERROR(SUM(Y6:AA6)/SUM(M6:O6)*100,"NA") -> 71.244002 | AO6: =IFERROR(SUM(AB6:AD6)/SUM(P6:R6)*100,"NA") -> 63.466572 | AP6: =IFERROR(SUM(AE6:AG6)/SUM(S6:U6)*100,"NA") -> 87.238027 | AQ6: =IFERROR(SUM(V6:AA6)/SUM(J6:O6)*100,"NA") -> 81.30837 | AR6: =IFERROR(SUM(AB6:AG6)/SUM(P6:U6)*100,"NA") -> 74.133008 | AS6: =IFERROR(SUM(V6:AG6)/SUM(J6:U6)*100,"NA") -> 78.163448
B7: HR | C7: HR | D7: =Hair!F102 -> 2.1250069 | E7: =Hair!G102 -> 3.5139921 | F7: =Hair!H102 -> 2.4579754 | G7: =Hair!I102 -> 1.9903063 | H7: =Hair!J102 -> 3.0273403 | I7: =Hair!K102 -> 2.9580323 | J7: =Hair!L102 -> 2.0713479 | K7: =Hair!M102 -> 2.5514775 | ... AG7: =Hair!AI102 -> 4.6 | AJ7: =IFERROR(AE7/S7*100,"NA") -> 107.22819 | AK7: =IFERROR(SUM(V7:AE7)/SUM(J7:S7)*100,"NA") -> 142.38635 | AL7: =IFERROR(SUM(AB7:AE7)/SUM(P7:S7)*100,"NA") -> 108.73088 | AM7: =IFERROR(SUM(V7:X7)/SUM(J7:L7)*100,"NA") -> 157.27905 | AN7: =IFERROR(SUM(Y7:AA7)/SUM(M7:O7)*100,"NA") -> 182.85487 | AO7: =IFERROR(SUM(AB7:AD7)/SUM(P7:R7)*100,"NA") -> 109.25245 | AP7: =IFERROR(SUM(AE7:AG7)/SUM(S7:U7)*100,"NA") -> 105.55763 | AQ7: =IFERROR(SUM(V7:AA7)/SUM(J7:O7)*100,"NA") -> 172.64479 | AR7: =IFERROR(SUM(AB7:AG7)/SUM(P7:U7)*100,"NA") -> 107.36271 | AS7: =IFERROR(SUM(V7:AG7)/SUM(J7:U7)*100,"NA") -> 134.95302
A8: Offtake | B8: Fabric | C8: Total | D8: =Fabric!F3 -> 3.2809509 | E8: =Fabric!G3 -> 4.8481083 | F8: =Fabric!H3 -> 3.9774963 | G8: =Fabric!I3 -> 5.4007097 | H8: =Fabric!J3 -> 6.0796203 | I8: =Fabric!K3 -> 3.6145921 | J8: =Fabric!L3 -> 4.1013033 | K8: =Fabric!M3 -> 3.8499108 | ... AG8: =Fabric!AI3 -> 6.36 | AJ8: =IFERROR(AE8/S8*100,"NA") -> 132.07981 | AK8: =IFERROR(SUM(V8:AE8)/SUM(J8:S8)*100,"NA") -> 102.0136 | AL8: =IFERROR(SUM(AB8:AE8)/SUM(P8:S8)*100,"NA") -> 97.763164 | AM8: =IFERROR(SUM(V8:X8)/SUM(J8:L8)*100,"NA") -> 116.29481 | AN8: =IFERROR(SUM(Y8:AA8)/SUM(M8:O8)*100,"NA") -> 98.168152 | AO8: =IFERROR(SUM(AB8:AD8)/SUM(P8:R8)*100,"NA") -> 86.269849 | AP8: =IFERROR(SUM(AE8:AG8)/SUM(S8:U8)*100,"NA") -> 120.61708 | AQ8: =IFERROR(SUM(V8:AA8)/SUM(J8:O8)*100,"NA") -> 104.90469 | AR8: =IFERROR(SUM(AB8:AG8)/SUM(P8:U8)*100,"NA") -> 103.84164 | AS8: =IFERROR(SUM(V8:AG8)/SUM(J8:U8)*100,"NA") -> 104.36191
B9: Ariel | C9: Total | D9: =Fabric!F4 -> 2.6030706 | E9: =Fabric!G4 -> 4.1279239 | F9: =Fabric!H4 -> 3.495721 | G9: =Fabric!I4 -> 4.2067224 | H9: =Fabric!J4 -> 4.7707851 | I9: =Fabric!K4 -> 3.018822 | J9: =Fabric!L4 -> 2.9258491 | K9: =Fabric!M4 -> 2.7380167 | ... AG9: =Fabric!AI4 -> 5 | AJ9: =IFERROR(AE9/S9*100,"NA") -> 156.17839 | AK9: =IFERROR(SUM(V9:AE9)/SUM(J9:S9)*100,"NA") -> 102.0453 | AL9: =IFERROR(SUM(AB9:AE9)/SUM(P9:S9)*100,"NA") -> 102.1589 | AM9: =IFERROR(SUM(V9:X9)/SUM(J9:L9)*100,"NA") -> 110.3396 | AN9: =IFERROR(SUM(Y9:AA9)/SUM(M9:O9)*100,"NA") -> 97.382682 | AO9: =IFERROR(SUM(AB9:AD9)/SUM(P9:R9)*100,"NA") -> 85.342832 | AP9: =IFERROR(SUM(AE9:AG9)/SUM(S9:U9)*100,"NA") -> 133.46615 | AQ9: =IFERROR(SUM(V9:AA9)/SUM(J9:O9)*100,"NA") -> 101.9726 | AR9: =IFERROR(SUM(AB9:AG9)/SUM(P9:U9)*100,"NA") -> 109.57376 | AS9: =IFERROR(SUM(V9:AG9)/SUM(J9:U9)*100,"NA") -> 105.74062
B10: Ariel | C10: Ariel LIQ | D10: =Fabric!F5 -> 0.5863432 | E10: =Fabric!G5 -> 0.9905921 | F10: =Fabric!H5 -> 0.68382615 | G10: =Fabric!I5 -> 0.74044633 | H10: =Fabric!J5 -> 1.1259407 | I10: =Fabric!K5 -> 1.0298289 | J10: =Fabric!L5 -> 0.75706357 | K10: =Fabric!M5 -> 0.90302607 | ... AG10: =Fabric!AI5 -> 1 | AJ10: =IFERROR(AE10/S10*100,"NA") -> 82.843843 | AK10: =IFERROR(SUM(V10:AE10)/SUM(J10:S10)*100,"NA") -> 106.34184 | AL10: =IFERROR(SUM(AB10:AE10)/SUM(P10:S10)*100,"NA") -> 80.772861 | AM10: =IFERROR(SUM(V10:X10)/SUM(J10:L10)*100,"NA") -> 124.91572 | AN10: =IFERROR(SUM(Y10:AA10)/SUM(M10:O10)*100,"NA") -> 127.84101 | AO10: =IFERROR(SUM(AB10:AD10)/SUM(P10:R10)*100,"NA") -> 80.065722 | AP10: =IFERROR(SUM(AE10:AG10)/SUM(S10:U10)*100,"NA") -> 94.661771 | AQ10: =IFERROR(SUM(V10:AA10)/SUM(J10:O10)*100,"NA") -> 126.32863 | AR10: =IFERROR(SUM(AB10:AG10)/SUM(P10:U10)*100,"NA") -> 87.496096 | AS10: =IFERROR(SUM(V10:AG10)/SUM(J10:U10)*100,"NA") -> 105.25257
B11: Ariel | C11: Ariel SUD | D11: =Fabric!F6 -> 2.0167274 | E11: =Fabric!G6 -> 3.1373318 | F11: =Fabric!H6 -> 2.8118949 | G11: =Fabric!I6 -> 3.4662761 | H11: =Fabric!J6 -> 3.6448444 | I11: =Fabric!K6 -> 1.988993 | J11: =Fabric!L6 -> 2.1687856 | K11: =Fabric!M6 -> 1.8349907 | ... AG11: =Fabric!AI6 -> 4 | AJ11: =IFERROR(AE11/S11*100,"NA") -> 183.62443 | AK11: =IFERROR(SUM(V11:AE11)/SUM(J11:S11)*100,"NA") -> 100.79135 | AL11: =IFERROR(SUM(AB11:AE11)/SUM(P11:S11)*100,"NA") -> 109.4402 | AM11: =IFERROR(SUM(V11:X11)/SUM(J11:L11)*100,"NA") -> 103.98833 | AN11: =IFERROR(SUM(Y11:AA11)/SUM(M11:O11)*100,"NA") -> 91.772745 | AO11: =IFERROR(SUM(AB11:AD11)/SUM(P11:R11)*100,"NA") -> 87.085799 | AP11: =IFERROR(SUM(AE11:AG11)/SUM(S11:U11)*100,"NA") -> 146.66846 | AQ11: =IFERROR(SUM(V11:AA11)/SUM(J11:O11)*100,"NA") -> 95.578058 | AR11: =IFERROR(SUM(AB11:AG11)/SUM(P11:U11)*100,"NA") -> 116.97583 | AS11: =IFERROR(SUM(V11:AG11)/SUM(J11:U11)*100,"NA") -> 105.88586
B12: Lenor | C12: Lenor | D12: =Fabric!F7 -> 0.67788021 | E12: =Fabric!G7 -> 0.72018447 | F12: =Fabric!H7 -> 0.45857487 | G12: =Fabric!I7 -> 1.1614319 | H12: =Fabric!J7 -> 1.2403566 | I12: =Fabric!K7 -> 0.51718814 | J12: =Fabric!L7 -> 1.1140854 | K12: =Fabric!M7 -> 1.0187183 | ... AG12: =Fabric!AI7 -> 1.16 | AJ12: =IFERROR(AE12/S12*100,"NA") -> 88.968946 | AK12: =IFERROR(SUM(V12:AE12)/SUM(J12:S12)*100,"NA") -> 91.571802 | AL12: =IFERROR(SUM(AB12:AE12)/SUM(P12:S12)*100,"NA") -> 87.599851 | AM12: =IFERROR(SUM(V12:X12)/SUM(J12:L12)*100,"NA") -> 100.43454 | AN12: =IFERROR(SUM(Y12:AA12)/SUM(M12:O12)*100,"NA") -> 90.223081 | AO12: =IFERROR(SUM(AB12:AD12)/SUM(P12:R12)*100,"NA") -> 87.122681 | AP12: =IFERROR(SUM(AE12:AG12)/SUM(S12:U12)*100,"NA") -> 99.973197 | AQ12: =IFERROR(SUM(V12:AA12)/SUM(J12:O12)*100,"NA") -> 94.591022 | AR12: =IFERROR(SUM(AB12:AG12)/SUM(P12:U12)*100,"NA") -> 93.433184 | AS12: =IFERROR(SUM(V12:AG12)/SUM(J12:U12)*100,"NA") -> 93.982554
B13: Bold | C13: Bold | D13: =Fabric!F8 -> 0 | E13: =Fabric!G8 -> 0 | F13: =Fabric!H8 -> 0.0232004 | G13: =Fabric!I8 -> 0.0325554 | H13: =Fabric!J8 -> 0.0684786 | I13: =Fabric!K8 -> 0.078582 | J13: =Fabric!L8 -> 0.0613688 | K13: =Fabric!M8 -> 0.0931758 | ... AG13: =Fabric!AI8 -> 0.2 | AJ13: =IFERROR(AE13/S13*100,"NA") -> 40.887747 | AK13: =IFERROR(SUM(V13:AE13)/SUM(J13:S13)*100,"NA") -> 191.50522 | AL13: =IFERROR(SUM(AB13:AE13)/SUM(P13:S13)*100,"NA") -> 74.942273 | AM13: =IFERROR(SUM(V13:X13)/SUM(J13:L13)*100,"NA") -> 498.9137 | AN13: =IFERROR(SUM(Y13:AA13)/SUM(M13:O13)*100,"NA") -> 258.7922 | AO13: =IFERROR(SUM(AB13:AD13)/SUM(P13:R13)*100,"NA") -> 104.56659 | AP13: =IFERROR(SUM(AE13:AG13)/SUM(S13:U13)*100,"NA") -> 49.221609 | AQ13: =IFERROR(SUM(V13:AA13)/SUM(J13:O13)*100,"NA") -> 376.21902 | AR13: =IFERROR(SUM(AB13:AG13)/SUM(P13:U13)*100,"NA") -> 64.332662 | AS13: =IFERROR(SUM(V13:AG13)/SUM(J13:U13)*100,"NA") -> 140.33097
A14: Offtake | B14: Oral | C14: Total | D14: =Oral!F3 -> 4.875333 | E14: =Oral!G3 -> 5.8560401 | F14: =Oral!H3 -> 4.9593555 | G14: =Oral!I3 -> 5.6983355 | H14: =Oral!J3 -> 7.1931792 | I14: =Oral!K3 -> 5.1703308 | J14: =Oral!L3 -> 4.1319147 | K14: =Oral!M3 -> 6.2557798 | ... AG14: =Oral!AI3 -> 6.358 | AJ14: =IFERROR(AE14/S14*100,"NA") -> 124.58012 | AK14: =IFERROR(SUM(V14:AE14)/SUM(J14:S14)*100,"NA") -> 120.32757 | AL14: =IFERROR(SUM(AB14:AE14)/SUM(P14:S14)*100,"NA") -> 113.07187 | AM14: =IFERROR(SUM(V14:X14)/SUM(J14:L14)*100,"NA") -> 105.46386 | AN14: =IFERROR(SUM(Y14:AA14)/SUM(M14:O14)*100,"NA") -> 143.0535 | AO14: =IFERROR(SUM(AB14:AD14)/SUM(P14:R14)*100,"NA") -> 109.57849 | AP14: =IFERROR(SUM(AE14:AG14)/SUM(S14:U14)*100,"NA") -> 109.24645 | AQ14: =IFERROR(SUM(V14:AA14)/SUM(J14:O14)*100,"NA") -> 124.69936 | AR14: =IFERROR(SUM(AB14:AG14)/SUM(P14:U14)*100,"NA") -> 109.40886 | AS14: =IFERROR(SUM(V14:AG14)/SUM(J14:U14)*100,"NA") -> 117.27025
B15: Oral-B | C15: OCM | D15: =Oral!F6 -> 2.132399 | E15: =Oral!G6 -> 2.0234925 | F15: =Oral!H6 -> 1.7709608 | G15: =Oral!I6 -> 1.546231 | H15: =Oral!J6 -> 1.8634206 | I15: =Oral!K6 -> 1.5405687 | J15: =Oral!L6 -> 1.0881453 | K15: =Oral!M6 -> 1.5423588 | ... AG15: =Oral!AI6 -> 1.34 | AJ15: =IFERROR(AE15/S15*100,"NA") -> 68.439707 | AK15: =IFERROR(SUM(V15:AE15)/SUM(J15:S15)*100,"NA") -> 78.561927 | AL15: =IFERROR(SUM(AB15:AE15)/SUM(P15:S15)*100,"NA") -> 59.341455 | AM15: =IFERROR(SUM(V15:X15)/SUM(J15:L15)*100,"NA") -> 107.02392 | AN15: =IFERROR(SUM(Y15:AA15)/SUM(M15:O15)*100,"NA") -> 79.86638 | AO15: =IFERROR(SUM(AB15:AD15)/SUM(P15:R15)*100,"NA") -> 56.594135 | AP15: =IFERROR(SUM(AE15:AG15)/SUM(S15:U15)*100,"NA") -> 77.923883 | AQ15: =IFERROR(SUM(V15:AA15)/SUM(J15:O15)*100,"NA") -> 92.614808 | AR15: =IFERROR(SUM(AB15:AG15)/SUM(P15:U15)*100,"NA") -> 66.65064 | AS15: =IFERROR(SUM(V15:AG15)/SUM(J15:U15)*100,"NA") -> 79.23916
B16: Oral-B | C16: OCP | D16: =Oral!F30 -> 1.2720631 | E16: =Oral!G30 -> 2.0157073 | F16: =Oral!H30 -> 1.5602139 | G16: =Oral!I30 -> 1.6239192 | H16: =Oral!J30 -> 2.2183716 | I16: =Oral!K30 -> 1.8884164 | J16: =Oral!L30 -> 1.5417833 | K16: =Oral!M30 -> 1.8191798 | ... AG16: =Oral!AI30 -> 2.2 | AJ16: =IFERROR(AE16/S16*100,"NA") -> 198.77855 | AK16: =IFERROR(SUM(V16:AE16)/SUM(J16:S16)*100,"NA") -> 164.43415 | AL16: =IFERROR(SUM(AB16:AE16)/SUM(P16:S16)*100,"NA") -> 177.51667 | AM16: =IFERROR(SUM(V16:X16)/SUM(J16:L16)*100,"NA") -> 124.51837 | AN16: =IFERROR(SUM(Y16:AA16)/SUM(M16:O16)*100,"NA") -> 185.69934 | AO16: =IFERROR(SUM(AB16:AD16)/SUM(P16:R16)*100,"NA") -> 171.78975 | AP16: =IFERROR(SUM(AE16:AG16)/SUM(S16:U16)*100,"NA") -> 119.69299 | AQ16: =IFERROR(SUM(V16:AA16)/SUM(J16:O16)*100,"NA") -> 155.73943 | AR16: =IFERROR(SUM(AB16:AG16)/SUM(P16:U16)*100,"NA") -> 143.80421 | AS16: =IFERROR(SUM(V16:AG16)/SUM(J16:U16)*100,"NA") -> 149.40422
B17: Crest | C17: OCM | D17: =Oral!F48 -> 1.4708709 | E17: =Oral!G48 -> 1.8168402 | F17: =Oral!H48 -> 1.6281809 | G17: =Oral!I48 -> 2.5281853 | H17: =Oral!J48 -> 3.1113871 | I17: =Oral!K48 -> 1.7413457 | J17: =Oral!L48 -> 1.5019861 | K17: =Oral!M48 -> 2.8942413 | ... AG17: =Oral!AI48 -> 2.818 | AJ17: =IFERROR(AE17/S17*100,"NA") -> 115.14355 | AK17: =IFERROR(SUM(V17:AE17)/SUM(J17:S17)*100,"NA") -> 117.16633 | AL17: =IFERROR(SUM(AB17:AE17)/SUM(P17:S17)*100,"NA") -> 103.71335 | AM17: =IFERROR(SUM(V17:X17)/SUM(J17:L17)*100,"NA") -> 92.053426 | AN17: =IFERROR(SUM(Y17:AA17)/SUM(M17:O17)*100,"NA") -> 155.11066 | AO17: =IFERROR(SUM(AB17:AD17)/SUM(P17:R17)*100,"NA") -> 99.846116 | AP17: =IFERROR(SUM(AE17:AG17)/SUM(S17:U17)*100,"NA") -> 123.14624 | AQ17: =IFERROR(SUM(V17:AA17)/SUM(J17:O17)*100,"NA") -> 123.65071 | AR17: =IFERROR(SUM(AB17:AG17)/SUM(P17:U17)*100,"NA") -> 111.931 | AS17: =IFERROR(SUM(V17:AG17)/SUM(J17:U17)*100,"NA") -> 118.63476
A18: Offtake | B18: Fem | C18: Total | D18: =Fem!F3 -> 2.7367969 | E18: =Fem!G3 -> 2.8721022 | F18: =Fem!H3 -> 2.8830513 | G18: =Fem!I3 -> 2.3754075 | H18: =Fem!J3 -> 3.2515813 | I18: =Fem!K3 -> 3.1253921 | J18: =Fem!L3 -> 2.1753227 | K18: =Fem!M3 -> 2.4889472 | ... AG18: =Fem!AI3 -> 3.89 | AJ18: =IFERROR(AE18/S18*100,"NA") -> 116.68216 | AK18: =IFERROR(SUM(V18:AE18)/SUM(J18:S18)*100,"NA") -> 115.20173 | AL18: =IFERROR(SUM(AB18:AE18)/SUM(P18:S18)*100,"NA") -> 127.28077 | AM18: =IFERROR(SUM(V18:X18)/SUM(J18:L18)*100,"NA") -> 102.30987 | AN18: =IFERROR(SUM(Y18:AA18)/SUM(M18:O18)*100,"NA") -> 110.24837 | AO18: =IFERROR(SUM(AB18:AD18)/SUM(P18:R18)*100,"NA") -> 130.60204 | AP18: =IFERROR(SUM(AE18:AG18)/SUM(S18:U18)*100,"NA") -> 90.334344 | AQ18: =IFERROR(SUM(V18:AA18)/SUM(J18:O18)*100,"NA") -> 106.78452 | AR18: =IFERROR(SUM(AB18:AG18)/SUM(P18:U18)*100,"NA") -> 106.39007 | AS18: =IFERROR(SUM(V18:AG18)/SUM(J18:U18)*100,"NA") -> 106.55931
B19: Whisper | C19: Ivory | D19: =Fem!F4 -> 1.4023466 | E19: =Fem!G4 -> 1.1811655 | F19: =Fem!H4 -> 1.160464 | G19: =Fem!I4 -> 1.2367935 | H19: =Fem!J4 -> 0.92683128 | I19: =Fem!K4 -> 0.8229503 | J19: =Fem!L4 -> 1.0779941 | K19: =Fem!M4 -> 1.1590808 | ... AG19: =Fem!AI4 -> 0.8 | AJ19: =IFERROR(AE19/S19*100,"NA") -> 102.608 | AK19: =IFERROR(SUM(V19:AE19)/SUM(J19:S19)*100,"NA") -> 110.49543 | AL19: =IFERROR(SUM(AB19:AE19)/SUM(P19:S19)*100,"NA") -> 111.63714 | AM19: =IFERROR(SUM(V19:X19)/SUM(J19:L19)*100,"NA") -> 90.740418 | AN19: =IFERROR(SUM(Y19:AA19)/SUM(M19:O19)*100,"NA") -> 124.13346 | AO19: =IFERROR(SUM(AB19:AD19)/SUM(P19:R19)*100,"NA") -> 114.99128 | AP19: =IFERROR(SUM(AE19:AG19)/SUM(S19:U19)*100,"NA") -> 108.33552 | AQ19: =IFERROR(SUM(V19:AA19)/SUM(J19:O19)*100,"NA") -> 109.7209 | AR19: =IFERROR(SUM(AB19:AG19)/SUM(P19:U19)*100,"NA") -> 111.91366 | AS19: =IFERROR(SUM(V19:AG19)/SUM(J19:U19)*100,"NA") -> 110.77166
B20: Whisper | C20: OVN Pants | D20: =Fem!F5 -> 0.55883643 | E20: =Fem!G5 -> 0.8378271 | F20: =Fem!H5 -> 0.82225735 | G20: =Fem!I5 -> 0.411808 | H20: =Fem!J5 -> 1.4820448 | I20: =Fem!K5 -> 1.5384022 | J20: =Fem!L5 -> 0.5014509 | K20: =Fem!M5 -> 0.60875691 | ... AG20: =Fem!AI5 -> 2.45 | AJ20: =IFERROR(AE20/S20*100,"NA") -> 186.03159 | AK20: =IFERROR(SUM(V20:AE20)/SUM(J20:S20)*100,"NA") -> 172.2054 | AL20: =IFERROR(SUM(AB20:AE20)/SUM(P20:S20)*100,"NA") -> 239.32413 | AM20: =IFERROR(SUM(V20:X20)/SUM(J20:L20)*100,"NA") -> 131.28894 | AN20: =IFERROR(SUM(Y20:AA20)/SUM(M20:O20)*100,"NA") -> 121.03147 | AO20: =IFERROR(SUM(AB20:AD20)/SUM(P20:R20)*100,"NA") -> 254.10399 | AP20: =IFERROR(SUM(AE20:AG20)/SUM(S20:U20)*100,"NA") -> 87.810365 | AQ20: =IFERROR(SUM(V20:AA20)/SUM(J20:O20)*100,"NA") -> 125.69838 | AR20: =IFERROR(SUM(AB20:AG20)/SUM(P20:U20)*100,"NA") -> 124.49212 | AS20: =IFERROR(SUM(V20:AG20)/SUM(J20:U20)*100,"NA") -> 124.84083
B21: Whisper | C21: Premium day | D21: =Fem!F6 -> 0.56522483 | E21: =Fem!G6 -> 0.57272804 | F21: =Fem!H6 -> 0.69025783 | G21: =Fem!I6 -> 0.55431169 | H21: =Fem!J6 -> 0.61951738 | I21: =Fem!K6 -> 0.54217269 | J21: =Fem!L6 -> 0.39921134 | K21: =Fem!M6 -> 0.47733278 | ... AG21: =Fem!AI6 -> 0.54 | AJ21: =IFERROR(AE21/S21*100,"NA") -> 96.798004 | AK21: =IFERROR(SUM(V21:AE21)/SUM(J21:S21)*100,"NA") -> 90.901417 | AL21: =IFERROR(SUM(AB21:AE21)/SUM(P21:S21)*100,"NA") -> 80.481816 | AM21: =IFERROR(SUM(V21:X21)/SUM(J21:L21)*100,"NA") -> 101.8977 | AN21: =IFERROR(SUM(Y21:AA21)/SUM(M21:O21)*100,"NA") -> 96.940949 | AO21: =IFERROR(SUM(AB21:AD21)/SUM(P21:R21)*100,"NA") -> 76.078119 | AP21: =IFERROR(SUM(AE21:AG21)/SUM(S21:U21)*100,"NA") -> 81.872808 | AQ21: =IFERROR(SUM(V21:AA21)/SUM(J21:O21)*100,"NA") -> 98.974364 | AR21: =IFERROR(SUM(AB21:AG21)/SUM(P21:U21)*100,"NA") -> 78.951852 | AS21: =IFERROR(SUM(V21:AG21)/SUM(J21:U21)*100,"NA") -> 88.010303
B22: Whisper | C22: OVN Pads | D22: =Fem!F7 -> 0.13845495 | E22: =Fem!G7 -> 0.14847617 | F22: =Fem!H7 -> 0.13136966 | G22: =Fem!I7 -> 0.10160958 | H22: =Fem!J7 -> 0.09878543 | I22: =Fem!K7 -> 0.09646766 | J22: =Fem!L7 -> 0.10474187 | K22: =Fem!M7 -> 0.09927894 | ... AG22: =Fem!AI7 -> 0 | AJ22: =IFERROR(AE22/S22*100,"NA") -> 36.369213 | AK22: =IFERROR(SUM(V22:AE22)/SUM(J22:S22)*100,"NA") -> 33.247822 | AL22: =IFERROR(SUM(AB22:AE22)/SUM(P22:S22)*100,"NA") -> 11.652816 | AM22: =IFERROR(SUM(V22:X22)/SUM(J22:L22)*100,"NA") -> 91.168913 | AN22: =IFERROR(SUM(Y22:AA22)/SUM(M22:O22)*100,"NA") -> 8.7838345 | AO22: =IFERROR(SUM(AB22:AD22)/SUM(P22:R22)*100,"NA") -> 6.05796 | AP22: =IFERROR(SUM(AE22:AG22)/SUM(S22:U22)*100,"NA") -> 9.8417492 | AQ22: =IFERROR(SUM(V22:AA22)/SUM(J22:O22)*100,"NA") -> 46.138553 | AR22: =IFERROR(SUM(AB22:AG22)/SUM(P22:U22)*100,"NA") -> 7.7814217 | AS22: =IFERROR(SUM(V22:AG22)/SUM(J22:U22)*100,"NA") -> 28.03425
B23: Whisper | C23: Other | D23: =Fem!F8 -> 0.071934085 | E23: =Fem!G8 -> 0.13190539 | F23: =Fem!H8 -> 0.0787025 | G23: =Fem!I8 -> 0.070884718 | H23: =Fem!J8 -> 0.12440242 | I23: =Fem!K8 -> 0.12539932 | J23: =Fem!L8 -> 0.09192452 | K23: =Fem!M8 -> 0.14449779 | ... AG23: =Fem!AI8 -> 0.1 | AJ23: =IFERROR(AE23/S23*100,"NA") -> 111.36713 | AK23: =IFERROR(SUM(V23:AE23)/SUM(J23:S23)*100,"NA") -> 84.640894 | AL23: =IFERROR(SUM(AB23:AE23)/SUM(P23:S23)*100,"NA") -> 83.92035 | AM23: =IFERROR(SUM(V23:X23)/SUM(J23:L23)*100,"NA") -> 83.452431 | AN23: =IFERROR(SUM(Y23:AA23)/SUM(M23:O23)*100,"NA") -> 86.719301 | AO23: =IFERROR(SUM(AB23:AD23)/SUM(P23:R23)*100,"NA") -> 75.961396 | AP23: =IFERROR(SUM(AE23:AG23)/SUM(S23:U23)*100,"NA") -> 105.53187 | AQ23: =IFERROR(SUM(V23:AA23)/SUM(J23:O23)*100,"NA") -> 85.080815 | AR23: =IFERROR(SUM(AB23:AG23)/SUM(P23:U23)*100,"NA") -> 89.481165 | AS23: =IFERROR(SUM(V23:AG23)/SUM(J23:U23)*100,"NA") -> 87.130502
A24: Offtake | B24: Home | C24: Total | D24: =Home!F3 -> 4.0659284 | E24: =Home!G3 -> 2.3311652 | F24: =Home!H3 -> 1.5093453 | G24: =Home!I3 -> 1.4853937 | H24: =Home!J3 -> 1.1837526 | I24: =Home!K3 -> 1.8465216 | J24: =Home!L3 -> 2.353358 | K24: =Home!M3 -> 1.9243719 | ... AG24: =Home!AI3 -> 2.46052 | AJ24: =IFERROR(AE24/S24*100,"NA") -> 119.9725 | AK24: =IFERROR(SUM(V24:AE24)/SUM(J24:S24)*100,"NA") -> 81.895548 | AL24: =IFERROR(SUM(AB24:AE24)/SUM(P24:S24)*100,"NA") -> 59.980211 | AM24: =IFERROR(SUM(V24:X24)/SUM(J24:L24)*100,"NA") -> 91.67876 | AN24: =IFERROR(SUM(Y24:AA24)/SUM(M24:O24)*100,"NA") -> 94.615713 | AO24: =IFERROR(SUM(AB24:AD24)/SUM(P24:R24)*100,"NA") -> 47.094828 | AP24: =IFERROR(SUM(AE24:AG24)/SUM(S24:U24)*100,"NA") -> 102.92728 | AQ24: =IFERROR(SUM(V24:AA24)/SUM(J24:O24)*100,"NA") -> 93.101988 | AR24: =IFERROR(SUM(AB24:AG24)/SUM(P24:U24)*100,"NA") -> 75.569705 | AS24: =IFERROR(SUM(V24:AG24)/SUM(J24:U24)*100,"NA") -> 85.000369
B25: Febreze | C25: Fabric Refresher | D25: =Home!F4 -> 2.6582155 | E25: =Home!G4 -> 0.4919301 | F25: =Home!H4 -> 0.3923011 | G25: =Home!I4 -> 0.38172873 | H25: =Home!J4 -> 0.47144285 | I25: =Home!K4 -> 1.4026337 | J25: =Home!L4 -> 2.0537536 | K25: =Home!M4 -> 0.85026768 | ... AG25: =Home!AI4 -> 1.1034 | AJ25: =IFERROR(AE25/S25*100,"NA") -> 127.68774 | AK25: =IFERROR(SUM(V25:AE25)/SUM(J25:S25)*100,"NA") -> 76.792387 | AL25: =IFERROR(SUM(AB25:AE25)/SUM(P25:S25)*100,"NA") -> 73.601092 | AM25: =IFERROR(SUM(V25:X25)/SUM(J25:L25)*100,"NA") -> 71.555143 | AN25: =IFERROR(SUM(Y25:AA25)/SUM(M25:O25)*100,"NA") -> 85.311522 | AO25: =IFERROR(SUM(AB25:AD25)/SUM(P25:R25)*100,"NA") -> 66.162039 | AP25: =IFERROR(SUM(AE25:AG25)/SUM(S25:U25)*100,"NA") -> 77.488378 | AQ25: =IFERROR(SUM(V25:AA25)/SUM(J25:O25)*100,"NA") -> 77.93894 | AR25: =IFERROR(SUM(AB25:AG25)/SUM(P25:U25)*100,"NA") -> 72.705509 | AS25: =IFERROR(SUM(V25:AG25)/SUM(J25:U25)*100,"NA") -> 75.69958
B26: Febreze | C26: Merlion | D26: =Home!F5 -> 1.4077129 | E26: =Home!G5 -> 1.8392351 | F26: =Home!H5 -> 1.1170442 | G26: =Home!I5 -> 1.103665 | H26: =Home!J5 -> 0.71230977 | I26: =Home!K5 -> 0.44388784 | J26: =Home!L5 -> 0.29960433 | K26: =Home!M5 -> 1.0741042 | ... AG26: =Home!AI5 -> 1.35712 | AJ26: =IFERROR(AE26/S26*100,"NA") -> 117.1165 | AK26: =IFERROR(SUM(V26:AE26)/SUM(J26:S26)*100,"NA") -> 87.116795 | AL26: =IFERROR(SUM(AB26:AE26)/SUM(P26:S26)*100,"NA") -> 51.084608 | AM26: =IFERROR(SUM(V26:X26)/SUM(J26:L26)*100,"NA") -> 120.0107 | AN26: =IFERROR(SUM(Y26:AA26)/SUM(M26:O26)*100,"NA") -> 105.47114 | AO26: =IFERROR(SUM(AB26:AD26)/SUM(P26:R26)*100,"NA") -> 33.179608 | AP26: =IFERROR(SUM(AE26:AG26)/SUM(S26:U26)*100,"NA") -> 134.59706 | AQ26: =IFERROR(SUM(V26:AA26)/SUM(J26:O26)*100,"NA") -> 112.58141 | AR26: =IFERROR(SUM(AB26:AG26)/SUM(P26:U26)*100,"NA") -> 78.316657 | AS26: =IFERROR(SUM(V26:AG26)/SUM(J26:U26)*100,"NA") -> 95.433197
A27: Offtake | B27: Skin | C27: Total | D27: =Skin!F3 -> 3.776986 | E27: =Skin!G3 -> 5.4227941 | F27: =Skin!H3 -> 3.9762773 | G27: =Skin!I3 -> 2.9057808 | H27: =Skin!J3 -> 3.8329953 | I27: =Skin!K3 -> 3.5466867 | J27: =Skin!L3 -> 4.8695032 | K27: =Skin!M3 -> 3.7218803 | ... AG27: =Skin!AI3 -> 9.15 | AJ27: =IFERROR(AE27/S27*100,"NA") -> 109.52049 | AK27: =IFERROR(SUM(V27:AE27)/SUM(J27:S27)*100,"NA") -> 135.51984 | AL27: =IFERROR(SUM(AB27:AE27)/SUM(P27:S27)*100,"NA") -> 111.51472 | AM27: =IFERROR(SUM(V27:X27)/SUM(J27:L27)*100,"NA") -> 126.66602 | AN27: =IFERROR(SUM(Y27:AA27)/SUM(M27:O27)*100,"NA") -> 178.8049 | AO27: =IFERROR(SUM(AB27:AD27)/SUM(P27:R27)*100,"NA") -> 112.27082 | AP27: =IFERROR(SUM(AE27:AG27)/SUM(S27:U27)*100,"NA") -> 109.67712 | AQ27: =IFERROR(SUM(V27:AA27)/SUM(J27:O27)*100,"NA") -> 153.79244 | AR27: =IFERROR(SUM(AB27:AG27)/SUM(P27:U27)*100,"NA") -> 110.77291 | AS27: =IFERROR(SUM(V27:AG27)/SUM(J27:U27)*100,"NA") -> 129.42507
B28: Olay | C28: RG | D28: =Skin!F4 -> 1.6345184 | E28: =Skin!G4 -> 1.8170267 | F28: =Skin!H4 -> 0.62381007 | G28: =Skin!I4 -> 0.53393293 | H28: =Skin!J4 -> 0.68026902 | I28: =Skin!K4 -> 0.44490422 | J28: =Skin!L4 -> 0.41393447 | K28: =Skin!M4 -> 0.82545993 | ... AG28: =Skin!AI4 -> 1 | AJ28: =IFERROR(AE28/S28*100,"NA") -> 49.078788 | AK28: =IFERROR(SUM(V28:AE28)/SUM(J28:S28)*100,"NA") -> 73.341511 | AL28: =IFERROR(SUM(AB28:AE28)/SUM(P28:S28)*100,"NA") -> 44.250571 | AM28: =IFERROR(SUM(V28:X28)/SUM(J28:L28)*100,"NA") -> 138.0293 | AN28: =IFERROR(SUM(Y28:AA28)/SUM(M28:O28)*100,"NA") -> 79.005608 | AO28: =IFERROR(SUM(AB28:AD28)/SUM(P28:R28)*100,"NA") -> 42.750068 | AP28: =IFERROR(SUM(AE28:AG28)/SUM(S28:U28)*100,"NA") -> 51.828915 | AQ28: =IFERROR(SUM(V28:AA28)/SUM(J28:O28)*100,"NA") -> 106.05268 | AR28: =IFERROR(SUM(AB28:AG28)/SUM(P28:U28)*100,"NA") -> 47.590367 | AS28: =IFERROR(SUM(V28:AG28)/SUM(J28:U28)*100,"NA") -> 68.193965
B29: Olay | C29: RG T&E | D29: =Skin!F5 -> 0.34007665 | E29: =Skin!G5 -> 0.36814122 | F29: =Skin!H5 -> 0.17168918 | G29: =Skin!I5 -> 0.17499089 | H29: =Skin!J5 -> 0.2096589 | I29: =Skin!K5 -> 0.1320686 | J29: =Skin!L5 -> 0.10950688 | K29: =Skin!M5 -> 0.75195251 | ... AG29: =Skin!AI5 -> 0.65 | AJ29: =IFERROR(AE29/S29*100,"NA") -> 76.78514 | AK29: =IFERROR(SUM(V29:AE29)/SUM(J29:S29)*100,"NA") -> 74.866258 | AL29: =IFERROR(SUM(AB29:AE29)/SUM(P29:S29)*100,"NA") -> 58.592738 | AM29: =IFERROR(SUM(V29:X29)/SUM(J29:L29)*100,"NA") -> 101.55644 | AN29: =IFERROR(SUM(Y29:AA29)/SUM(M29:O29)*100,"NA") -> 82.817615 | AO29: =IFERROR(SUM(AB29:AD29)/SUM(P29:R29)*100,"NA") -> 53.730636 | AP29: =IFERROR(SUM(AE29:AG29)/SUM(S29:U29)*100,"NA") -> 67.746819 | AQ29: =IFERROR(SUM(V29:AA29)/SUM(J29:O29)*100,"NA") -> 89.476735 | AR29: =IFERROR(SUM(AB29:AG29)/SUM(P29:U29)*100,"NA") -> 60.239582 | AS29: =IFERROR(SUM(V29:AG29)/SUM(J29:U29)*100,"NA") -> 72.827064
B30: Olay | C30: Magic | D30: =Skin!F6 -> 0 | E30: =Skin!G6 -> 0 | F30: =Skin!H6 -> 0 | G30: =Skin!I6 -> 0 | H30: =Skin!J6 -> 0 | I30: =Skin!K6 -> 0 | J30: =Skin!L6 -> 0 | K30: =Skin!M6 -> 0 | ... AG30: =Skin!AI6 -> 1.8 | AJ30: =IFERROR(AE30/S30*100,"NA") -> NA | AK30: =IFERROR(SUM(V30:AE30)/SUM(J30:S30)*100,"NA") -> NA | AL30: =IFERROR(SUM(AB30:AE30)/SUM(P30:S30)*100,"NA") -> NA | AM30: =IFERROR(SUM(V30:X30)/SUM(J30:L30)*100,"NA") -> NA | AN30: =IFERROR(SUM(Y30:AA30)/SUM(M30:O30)*100,"NA") -> NA | AO30: =IFERROR(SUM(AB30:AD30)/SUM(P30:R30)*100,"NA") -> NA | AP30: =IFERROR(SUM(AE30:AG30)/SUM(S30:U30)*100,"NA") -> NA | AQ30: =IFERROR(SUM(V30:AA30)/SUM(J30:O30)*100,"NA") -> NA | AR30: =IFERROR(SUM(AB30:AG30)/SUM(P30:U30)*100,"NA") -> NA | AS30: =IFERROR(SUM(V30:AG30)/SUM(J30:U30)*100,"NA") -> NA
B31: Olay | C31: WR | D31: =Skin!F7 -> 0.93422827 | E31: =Skin!G7 -> 2.1415075 | F31: =Skin!H7 -> 2.3207923 | G31: =Skin!I7 -> 1.3661058 | H31: =Skin!J7 -> 1.7731532 | I31: =Skin!K7 -> 2.1702833 | J31: =Skin!L7 -> 3.6342716 | K31: =Skin!M7 -> 1.2701596 | ... AG31: =Skin!AI7 -> 2 | AJ31: =IFERROR(AE31/S31*100,"NA") -> 55.940207 | AK31: =IFERROR(SUM(V31:AE31)/SUM(J31:S31)*100,"NA") -> 108.19696 | AL31: =IFERROR(SUM(AB31:AE31)/SUM(P31:S31)*100,"NA") -> 67.657338 | AM31: =IFERROR(SUM(V31:X31)/SUM(J31:L31)*100,"NA") -> 138.71767 | AN31: =IFERROR(SUM(Y31:AA31)/SUM(M31:O31)*100,"NA") -> 125.6801 | AO31: =IFERROR(SUM(AB31:AD31)/SUM(P31:R31)*100,"NA") -> 74.353379 | AP31: =IFERROR(SUM(AE31:AG31)/SUM(S31:U31)*100,"NA") -> 42.765203 | AQ31: =IFERROR(SUM(V31:AA31)/SUM(J31:O31)*100,"NA") -> 132.84346 | AR31: =IFERROR(SUM(AB31:AG31)/SUM(P31:U31)*100,"NA") -> 52.731952 | AS31: =IFERROR(SUM(V31:AG31)/SUM(J31:U31)*100,"NA") -> 88.718724
B32: Olay | C32: OLAYII | D32: =Skin!F8 -> 0.86816265 | E32: =Skin!G8 -> 1.0961188 | F32: =Skin!H8 -> 0.8599857 | G32: =Skin!I8 -> 0.8307512 | H32: =Skin!J8 -> 1.1699142 | I32: =Skin!K8 -> 0.79943056 | J32: =Skin!L8 -> 0.71179033 | K32: =Skin!M8 -> 0.87430824 | ... AG32: =Skin!AI8 -> 0.7 | AJ32: =IFERROR(AE32/S32*100,"NA") -> 94.841461 | AK32: =IFERROR(SUM(V32:AE32)/SUM(J32:S32)*100,"NA") -> 87.828901 | AL32: =IFERROR(SUM(AB32:AE32)/SUM(P32:S32)*100,"NA") -> 81.026509 | AM32: =IFERROR(SUM(V32:X32)/SUM(J32:L32)*100,"NA") -> 90.122923 | AN32: =IFERROR(SUM(Y32:AA32)/SUM(M32:O32)*100,"NA") -> 93.845322 | AO32: =IFERROR(SUM(AB32:AD32)/SUM(P32:R32)*100,"NA") -> 77.149905 | AP32: =IFERROR(SUM(AE32:AG32)/SUM(S32:U32)*100,"NA") -> 89.74305 | AQ32: =IFERROR(SUM(V32:AA32)/SUM(J32:O32)*100,"NA") -> 92.18649 | AR32: =IFERROR(SUM(AB32:AG32)/SUM(P32:U32)*100,"NA") -> 83.094731 | AS32: =IFERROR(SUM(V32:AG32)/SUM(J32:U32)*100,"NA") -> 87.763099
B33: Olay | C33: Pro-X | AE33: =Skin!AG9 -> 0 | AF33: =Skin!AH9 -> 1 | AG33: =Skin!AI9 -> 3 | AJ33: =IFERROR(AE33/S33*100,"NA") -> NA | AK33: =IFERROR(SUM(V33:AE33)/SUM(J33:S33)*100,"NA") -> NA | AL33: =IFERROR(SUM(AB33:AE33)/SUM(P33:S33)*100,"NA") -> NA | AM33: =IFERROR(SUM(V33:X33)/SUM(J33:L33)*100,"NA") -> NA | AN33: =IFERROR(SUM(Y33:AA33)/SUM(M33:O33)*100,"NA") -> NA | AO33: =IFERROR(SUM(AB33:AD33)/SUM(P33:R33)*100,"NA") -> NA | AP33: =IFERROR(SUM(AE33:AG33)/SUM(S33:U33)*100,"NA") -> NA | AQ33: =IFERROR(SUM(V33:AA33)/SUM(J33:O33)*100,"NA") -> NA | AR33: =IFERROR(SUM(AB33:AG33)/SUM(P33:U33)*100,"NA") -> NA | AS33: =IFERROR(SUM(V33:AG33)/SUM(J33:U33)*100,"NA") -> NA
A34: Offtake | B34: Shave | C34: Total | D34: =Shave!F3 -> 0.84207448 | E34: =Shave!G3 -> 1.195544 | F34: =Shave!H3 -> 0.74396439 | G34: =Shave!I3 -> 0.81556211 | H34: =Shave!J3 -> 1.0207331 | I34: =Shave!K3 -> 0.79918778 | J34: =Shave!L3 -> 0.80561642 | K34: =Shave!M3 -> 1.0013544 | ... AG34: =Shave!AI3 -> 1.0024509 | AJ34: =IFERROR(AE34/S34*100,"NA") -> 128.49922 | AK34: =IFERROR(SUM(V34:AE34)/SUM(J34:S34)*100,"NA") -> 109.36445 | AL34: =IFERROR(SUM(AB34:AE34)/SUM(P34:S34)*100,"NA") -> 104.05968 | AM34: =IFERROR(SUM(V34:X34)/SUM(J34:L34)*100,"NA") -> 109.43166 | AN34: =IFERROR(SUM(Y34:AA34)/SUM(M34:O34)*100,"NA") -> 116.77722 | AO34: =IFERROR(SUM(AB34:AD34)/SUM(P34:R34)*100,"NA") -> 97.084797 | AP34: =IFERROR(SUM(AE34:AG34)/SUM(S34:U34)*100,"NA") -> 108.84865 | AQ34: =IFERROR(SUM(V34:AA34)/SUM(J34:O34)*100,"NA") -> 113.25913 | AR34: =IFERROR(SUM(AB34:AG34)/SUM(P34:U34)*100,"NA") -> 102.75486 | AS34: =IFERROR(SUM(V34:AG34)/SUM(J34:U34)*100,"NA") -> 107.75062
A35: Sell-Thru | B35: Total | C35: Total | D35: =SUM(D36,D41,D47,D51,D57,D60,D67) -> 30.327188 | E35: =SUM(E36,E41,E47,E51,E57,E60,E67) -> 27.337312 | F35: =SUM(F36,F41,F47,F51,F57,F60,F67) -> 25.749337 | G35: =SUM(G36,G41,G47,G51,G57,G60,G67) -> 23.580707 | H35: =SUM(H36,H41,H47,H51,H57,H60,H67) -> 31.153656 | I35: =SUM(I36,I41,I47,I51,I57,I60,I67) -> 25.84648 | J35: =SUM(J36,J41,J47,J51,J57,J60,J67) -> 37.724341 | K35: =SUM(K36,K41,K47,K51,K57,K60,K67) -> 24.662676 | ... AG35: =SUM(AG36,AG41,AG47,AG51,AG57,AG60,AG67) -> 44.967479 | AJ35: =IFERROR(AE35/S35*100,"NA") -> 53.942773 | AK35: =IFERROR(SUM(V35:AE35)/SUM(J35:S35)*100,"NA") -> 112.77574 | AL35: =IFERROR(SUM(AB35:AE35)/SUM(P35:S35)*100,"NA") -> 90.35071 | AM35: =IFERROR(SUM(V35:X35)/SUM(J35:L35)*100,"NA") -> 131.7174 | AN35: =IFERROR(SUM(Y35:AA35)/SUM(M35:O35)*100,"NA") -> 126.64238 | AO35: =IFERROR(SUM(AB35:AD35)/SUM(P35:R35)*100,"NA") -> 107.98024 | AP35: =IFERROR(SUM(AE35:AG35)/SUM(S35:U35)*100,"NA") -> 119.69611 | AQ35: =IFERROR(SUM(V35:AA35)/SUM(J35:O35)*100,"NA") -> 128.95275 | AR35: =IFERROR(SUM(AB35:AG35)/SUM(P35:U35)*100,"NA") -> 114.3125 | AS35: =IFERROR(SUM(V35:AG35)/SUM(J35:U35)*100,"NA") -> 121.42732
A36: Sell-Thru | B36: Hair | C36: Total | D36: =Hair!F4 -> 9.7945465 | E36: =Hair!G4 -> 6.2381746 | F36: =Hair!H4 -> 7.8761366 | G36: =Hair!I4 -> 5.1384893 | H36: =Hair!J4 -> 10.926275 | I36: =Hair!K4 -> 6.5666194 | J36: =Hair!L4 -> 8.0995559 | K36: =Hair!M4 -> 6.3692824 | ... AG36: =Hair!AI4 -> 14.6197 | AJ36: =IFERROR(AE36/S36*100,"NA") -> 77.39681 | AK36: =IFERROR(SUM(V36:AE36)/SUM(J36:S36)*100,"NA") -> 128.2623 | AL36: =IFERROR(SUM(AB36:AE36)/SUM(P36:S36)*100,"NA") -> 120.96407 | AM36: =IFERROR(SUM(V36:X36)/SUM(J36:L36)*100,"NA") -> 138.42212 | AN36: =IFERROR(SUM(Y36:AA36)/SUM(M36:O36)*100,"NA") -> 129.91 | AO36: =IFERROR(SUM(AB36:AD36)/SUM(P36:R36)*100,"NA") -> 141.89331 | AP36: =IFERROR(SUM(AE36:AG36)/SUM(S36:U36)*100,"NA") -> 138.40585 | AQ36: =IFERROR(SUM(V36:AA36)/SUM(J36:O36)*100,"NA") -> 133.34775 | AR36: =IFERROR(SUM(AB36:AG36)/SUM(P36:U36)*100,"NA") -> 139.98218 | AS36: =IFERROR(SUM(V36:AG36)/SUM(J36:U36)*100,"NA") -> 136.73216
B37: HNS | C37: HNS | D37: =Hair!F24 -> 1.2118073 | E37: =Hair!G24 -> 1.1418995 | F37: =Hair!H24 -> 1.5661167 | G37: =Hair!I24 -> 0.98512224 | H37: =Hair!J24 -> 3.4274797 | I37: =Hair!K24 -> 1.3125103 | J37: =Hair!L24 -> 2.503759 | K37: =Hair!M24 -> 0.78586634 | ... AG37: =Hair!AI24 -> 2.49 | AJ37: =IFERROR(AE37/S37*100,"NA") -> 31.82573 | AK37: =IFERROR(SUM(V37:AE37)/SUM(J37:S37)*100,"NA") -> 102.21504 | AL37: =IFERROR(SUM(AB37:AE37)/SUM(P37:S37)*100,"NA") -> 96.404858 | AM37: =IFERROR(SUM(V37:X37)/SUM(J37:L37)*100,"NA") -> 106.91484 | AN37: =IFERROR(SUM(Y37:AA37)/SUM(M37:O37)*100,"NA") -> 107.5161 | AO37: =IFERROR(SUM(AB37:AD37)/SUM(P37:R37)*100,"NA") -> 178.73163 | AP37: =IFERROR(SUM(AE37:AG37)/SUM(S37:U37)*100,"NA") -> 75.479014 | AQ37: =IFERROR(SUM(V37:AA37)/SUM(J37:O37)*100,"NA") -> 107.25253 | AR37: =IFERROR(SUM(AB37:AG37)/SUM(P37:U37)*100,"NA") -> 106.03162 | AS37: =IFERROR(SUM(V37:AG37)/SUM(J37:U37)*100,"NA") -> 106.56522
B38: PTN | C38: PTN | D38: =Hair!F63 -> 2.9362766 | E38: =Hair!G63 -> 2.0315401 | F38: =Hair!H63 -> 4.2586452 | G38: =Hair!I63 -> 2.4166023 | H38: =Hair!J63 -> 2.4171462 | I38: =Hair!K63 -> 3.1386365 | J38: =Hair!L63 -> 2.5800147 | K38: =Hair!M63 -> 2.7070763 | ... AG38: =Hair!AI63 -> 4.4025 | AJ38: =IFERROR(AE38/S38*100,"NA") -> 79.319678 | AK38: =IFERROR(SUM(V38:AE38)/SUM(J38:S38)*100,"NA") -> 129.42266 | AL38: =IFERROR(SUM(AB38:AE38)/SUM(P38:S38)*100,"NA") -> 154.58406 | AM38: =IFERROR(SUM(V38:X38)/SUM(J38:L38)*100,"NA") -> 163.73872 | AN38: =IFERROR(SUM(Y38:AA38)/SUM(M38:O38)*100,"NA") -> 89.698566 | AO38: =IFERROR(SUM(AB38:AD38)/SUM(P38:R38)*100,"NA") -> 194.61056 | AP38: =IFERROR(SUM(AE38:AG38)/SUM(S38:U38)*100,"NA") -> 130.10535 | AQ38: =IFERROR(SUM(V38:AA38)/SUM(J38:O38)*100,"NA") -> 116.00847 | AR38: =IFERROR(SUM(AB38:AG38)/SUM(P38:U38)*100,"NA") -> 155.48735 | AS38: =IFERROR(SUM(V38:AG38)/SUM(J38:U38)*100,"NA") -> 134.53798
B39: Pert | C39: Pert | D39: =Hair!F93 -> 0.1970903 | E39: =Hair!G93 -> 0.9277614 | F39: =Hair!H93 -> 0.6433691 | G39: =Hair!I93 -> 0.3942249 | H39: =Hair!J93 -> 0.4704229 | I39: =Hair!K93 -> 0.3001885 | J39: =Hair!L93 -> 1.0208628 | K39: =Hair!M93 -> 0.6890876 | ... AG39: =Hair!AI93 -> 1.4272 | AJ39: =IFERROR(AE39/S39*100,"NA") -> 127.40464 | AK39: =IFERROR(SUM(V39:AE39)/SUM(J39:S39)*100,"NA") -> 74.909692 | AL39: =IFERROR(SUM(AB39:AE39)/SUM(P39:S39)*100,"NA") -> 112.09903 | AM39: =IFERROR(SUM(V39:X39)/SUM(J39:L39)*100,"NA") -> 100.5317 | AN39: =IFERROR(SUM(Y39:AA39)/SUM(M39:O39)*100,"NA") -> 43.581288 | AO39: =IFERROR(SUM(AB39:AD39)/SUM(P39:R39)*100,"NA") -> 107.50615 | AP39: =IFERROR(SUM(AE39:AG39)/SUM(S39:U39)*100,"NA") -> 213.18313 | AQ39: =IFERROR(SUM(V39:AA39)/SUM(J39:O39)*100,"NA") -> 68.682053 | AR39: =IFERROR(SUM(AB39:AG39)/SUM(P39:U39)*100,"NA") -> 168.52592 | AS39: =IFERROR(SUM(V39:AG39)/SUM(J39:U39)*100,"NA") -> 92.005877
B40: HR | C40: HR | D40: =Hair!F114 -> 5.4493724 | E40: =Hair!G114 -> 2.1369736 | F40: =Hair!H114 -> 1.4080056 | G40: =Hair!I114 -> 1.3425398 | H40: =Hair!J114 -> 4.6112264 | I40: =Hair!K114 -> 1.8152841 | J40: =Hair!L114 -> 1.9949193 | K40: =Hair!M114 -> 2.1872521 | ... AG40: =Hair!AI114 -> 6.3 | AJ40: =IFERROR(AE40/S40*100,"NA") -> 137.00669 | AK40: =IFERROR(SUM(V40:AE40)/SUM(J40:S40)*100,"NA") -> 150.53205 | AL40: =IFERROR(SUM(AB40:AE40)/SUM(P40:S40)*100,"NA") -> 108.44591 | AM40: =IFERROR(SUM(V40:X40)/SUM(J40:L40)*100,"NA") -> 139.45742 | AN40: =IFERROR(SUM(Y40:AA40)/SUM(M40:O40)*100,"NA") -> 233.77102 | AO40: =IFERROR(SUM(AB40:AD40)/SUM(P40:R40)*100,"NA") -> 101.53227 | AP40: =IFERROR(SUM(AE40:AG40)/SUM(S40:U40)*100,"NA") -> 201.57285 | AQ40: =IFERROR(SUM(V40:AA40)/SUM(J40:O40)*100,"NA") -> 192.22581 | AR40: =IFERROR(SUM(AB40:AG40)/SUM(P40:U40)*100,"NA") -> 142.28612 | AS40: =IFERROR(SUM(V40:AG40)/SUM(J40:U40)*100,"NA") -> 163.5744
...

Sheet Hair
F1: Actual | G1: Actual | H1: Actual | I1: Actual | J1: Actual | K1: Actual | L1: Actual | M1: Actual | N1: Actual | O1: Actual | P1: Actual | Q1: Actual | R1: Actual | S1: Actual | T1: Actual | U1: Actual | V1: Actual | W1: Actual | X1: Actual | Y1: Actual | Z1: Actual | AA1: Actual | AB1: Actual | AC1: Actual | AD1: Actual | AE1: Actual | AF1: Actual | AG1: Actual | AH1: Fcst | AI1: Fcst | AK1: Last Month
A2: Type | B2: BB | C2: Category | D2: Brand | E2: Line-up | F2: 202401 | G2: 202402 | H2: 202403 | I2: 202404 | J2: 202405 | K2: 202406 | L2: 202407 | M2: 202408 | N2: 202409 | O2: 202410 | P2: 202411 | Q2: 202412 | R2: 202501 | S2: 202502 | T2: 202503 | U2: 202504 | V2: 202505 | W2: 202506 | X2: 202507 | Y2: 202508 | Z2: 202509 | AA2: 202510 | AB2: 202511 | AC2: 202512 | AD2: 202601 | AE2: 202602 | AF2: 202603 | AG2: 202604 | AH2: 202605 | AI2: 202606 | AK2: Assumption | AL2: +/- | AN2: CM | AO2: FYTD | AP2: CYTD | AQ2: JAS | AR2: OND | AS2: JFM | AT2: AMJ | AU2: 1H | AV2: 2H | AW2: FY
A3: Offtake | B3: Total | C3: Hair | D3: Total | E3: Total | F3: =F6+F42+F84+F102 -> 7.2976789 | G3: =G6+G42+G84+G102 -> 9.0880794 | H3: =H6+H42+H84+H102 -> 7.547991 | I3: =I6+I42+I84+I102 -> 6.8362572 | J3: =J6+J42+J84+J102 -> 7.7994483 | K3: =K6+K42+K84+K102 -> 7.7877277 | L3: =L6+L42+L84+L102 -> 7.0275254 | M3: =M6+M42+M84+M102 -> 7.4311767 | ... AI3: =AI6+AI42+AI84+AI102 -> 12.4325 | AK3: 11.44572 | AL3: =AG3-AK3 -> 0.17184255 | AN3: =IFERROR(AG3/U3*100,"NA") -> 113.80084 | AO3: =IFERROR(SUM(X3:AG3)/SUM(L3:U3)*100,"NA") -> 129.86905 | AP3: =IFERROR(SUM(AD3:AG3)/SUM(R3:U3)*100,"NA") -> 113.9543 | AQ3: =IFERROR(SUM(X3:Z3)/SUM(L3:N3)*100,"NA") -> 134.99625 | AR3: =IFERROR(SUM(AA3:AC3)/SUM(O3:Q3)*100,"NA") -> 146.53094 | AS3: =IFERROR(SUM(AD3:AF3)/SUM(R3:T3)*100,"NA") -> 114.01157 | AT3: =IFERROR(SUM(AG3:AI3)/SUM(U3:W3)*100,"NA") -> 106.56187 | AU3: =IFERROR(SUM(X3:AC3)/SUM(L3:Q3)*100,"NA") -> 141.69283 | AV3: =IFERROR(SUM(AD3:AI3)/SUM(R3:W3)*100,"NA") -> 109.91866 | AW3: =IFERROR(SUM(X3:AI3)/SUM(L3:W3)*100,"NA") -> 124.35693 | AY3: =AVERAGE(AG3:AI3)/AVERAGE(AD3:AF3,X3:AB3)*100 -> 111.84315
A4: Sell-Thru | B4: Total | C4: Hair | D4: Total | E4: Total | F4: =F24+F63+F93+F114 -> 9.7945465 | G4: =G24+G63+G93+G114 -> 6.2381746 | H4: =H24+H63+H93+H114 -> 7.8761366 | I4: =I24+I63+I93+I114 -> 5.1384893 | J4: =J24+J63+J93+J114 -> 10.926275 | K4: =K24+K63+K93+K114 -> 6.5666194 | L4: =L24+L63+L93+L114 -> 8.0995559 | M4: =M24+M63+M93+M114 -> 6.3692824 | ... AI4: =AI24+AI63+AI93+AI114 -> 14.6197 | AK4: 20.37572 | AL4: =AG4-AK4 -> -10.16572 | AN4: =IFERROR(AG4/U4*100,"NA") -> 77.39681 | AO4: =IFERROR(SUM(X4:AG4)/SUM(L4:U4)*100,"NA") -> 128.2623 | AP4: =IFERROR(SUM(AD4:AG4)/SUM(R4:U4)*100,"NA") -> 120.96407 | AQ4: =IFERROR(SUM(X4:Z4)/SUM(L4:N4)*100,"NA") -> 138.42212 | AR4: =IFERROR(SUM(AA4:AC4)/SUM(O4:Q4)*100,"NA") -> 129.91 | AS4: =IFERROR(SUM(AD4:AF4)/SUM(R4:T4)*100,"NA") -> 141.89331 | AT4: =IFERROR(SUM(AG4:AI4)/SUM(U4:W4)*100,"NA") -> 138.40585 | AU4: =IFERROR(SUM(X4:AC4)/SUM(L4:Q4)*100,"NA") -> 133.34775 | AV4: =IFERROR(SUM(AD4:AI4)/SUM(R4:W4)*100,"NA") -> 139.98218 | AW4: =IFERROR(SUM(X4:AI4)/SUM(L4:W4)*100,"NA") -> 136.73216
A5: Sell-in | B5: Total | C5: Hair | D5: Total | E5: Total | F5: =F126+F128+F130+F132 -> 10.280722 | G5: =G126+G128+G130+G132 -> 8.4725032 | H5: =H126+H128+H130+H132 -> 11.793991 | I5: =I126+I128+I130+I132 -> 5.1878484 | J5: =J126+J128+J130+J132 -> 16.043001 | K5: =K126+K128+K130+K132 -> 2.6986178 | L5: =L126+L128+L130+L132 -> 9.4095547 | M5: =M126+M128+M130+M132 -> 7.7307954 | ... AI5: =AI126+AI128+AI130+AI132 -> 14.6197 | AK5: 20.37572 | AL5: =AG5-AK5 -> -4.9334612 | AN5: =IFERROR(AG5/U5*100,"NA") -> 131.86886 | AO5: =IFERROR(SUM(X5:AG5)/SUM(L5:U5)*100,"NA") -> 131.29387 | AP5: =IFERROR(SUM(AD5:AG5)/SUM(R5:U5)*100,"NA") -> 137.9054 | AQ5: =IFERROR(SUM(X5:Z5)/SUM(L5:N5)*100,"NA") -> 127.8051 | AR5: =IFERROR(SUM(AA5:AC5)/SUM(O5:Q5)*100,"NA") -> 126.34259 | AS5: =IFERROR(SUM(AD5:AF5)/SUM(R5:T5)*100,"NA") -> 140.24265 | AT5: =IFERROR(SUM(AG5:AI5)/SUM(U5:W5)*100,"NA") -> 140.55609 | AU5: =IFERROR(SUM(X5:AC5)/SUM(L5:Q5)*100,"NA") -> 126.96908 | AV5: =IFERROR(SUM(AD5:AI5)/SUM(R5:W5)*100,"NA") -> 140.40608 | AW5: =IFERROR(SUM(X5:AI5)/SUM(L5:W5)*100,"NA") -> 133.63771
A6: Offtake | B6: Total | C6: Hair | D6: HNS | E6: Total | F6: =F10+F11 -> 1.1561017 | G6: =G10+G11 -> 1.520378 | H6: =H10+H11 -> 1.4297258 | I6: =I10+I11 -> 1.1546554 | J6: =J10+J11 -> 1.4983956 | K6: =K10+K11 -> 1.8250481 | L6: =L10+L11 -> 1.485706 | M6: =M10+M11 -> 1.6607624 | ... AI6: =AI10+AI11 -> 2.47 | AK6: 1.62 | AL6: =AG6-AK6 -> 0.4581516 | AN6: =IFERROR(AG6/U6*100,"NA") -> 75.790763 | AO6: =IFERROR(SUM(X6:AG6)/SUM(L6:U6)*100,"NA") -> 116.09933 | AP6: =IFERROR(SUM(AD6:AG6)/SUM(R6:U6)*100,"NA") -> 97.696861 | AQ6: =IFERROR(SUM(X6:Z6)/SUM(L6:N6)*100,"NA") -> 126.34213 | AR6: =IFERROR(SUM(AA6:AC6)/SUM(O6:Q6)*100,"NA") -> 133.71547 | AS6: =IFERROR(SUM(AD6:AF6)/SUM(R6:T6)*100,"NA") -> 111.11733 | AT6: =IFERROR(SUM(AG6:AI6)/SUM(U6:W6)*100,"NA") -> 86.875097 | AU6: =IFERROR(SUM(X6:AC6)/SUM(L6:Q6)*100,"NA") -> 130.18317 | AV6: =IFERROR(SUM(AD6:AI6)/SUM(R6:W6)*100,"NA") -> 95.846749 | AW6: =IFERROR(SUM(X6:AI6)/SUM(L6:W6)*100,"NA") -> 110.89104
A7: Offtake | B7: Total | C7: Hair | D7: HNS | E7: Ironman | F7: =SUMIFS('Offtake Raw'!H:H,'Offtake Raw'!$C:$C,Hair!$D7,'Offtake Raw'!$D:$D,Hair!$E7)/1000000 -> 0.2207382 | G7: =SUMIFS('Offtake Raw'!I:I,'Offtake Raw'!$C:$C,Hair!$D7,'Offtake Raw'!$D:$D,Hair!$E7)/1000000 -> 0.2234718 | H7: =SUMIFS('Offtake Raw'!J:J,'Offtake Raw'!$C:$C,Hair!$D7,'Offtake Raw'!$D:$D,Hair!$E7)/1000000 -> 0.2287112 | I7: =SUMIFS('Offtake Raw'!K:K,'Offtake Raw'!$C:$C,Hair!$D7,'Offtake Raw'!$D:$D,Hair!$E7)/1000000 -> 0.2293946 | J7: =SUMIFS('Offtake Raw'!L:L,'Offtake Raw'!$C:$C,Hair!$D7,'Offtake Raw'!$D:$D,Hair!$E7)/1000000 -> 0.1949968 | K7: =SUMIFS('Offtake Raw'!M:M,'Offtake Raw'!$C:$C,Hair!$D7,'Offtake Raw'!$D:$D,Hair!$E7)/1000000 -> 0.1883906 | L7: =SUMIFS('Offtake Raw'!N:N,'Offtake Raw'!$C:$C,Hair!$D7,'Offtake Raw'!$D:$D,Hair!$E7)/1000000 -> 0.2235924 | M7: =SUMIFS('Offtake Raw'!O:O,'Offtake Raw'!$C:$C,Hair!$D7,'Offtake Raw'!$D:$D,Hair!$E7)/1000000 -> 0.4734448 | N7: =SUMIFS('Offtake Raw'!P:P,'Offtake Raw'!$C:$C,Hair!$D7,'Offtake Raw'!$D:$D,Hair!$E7)/1000000 -> 0.360523 | O7: =SUMIFS('Offtake Raw'!Q:Q,'Offtake Raw'!$C:$C,Hair!$D7,'Offtake Raw'!$D:$D,Hair!$E7)/1000000 -> 0.425259 | P7: =SUMIFS('Offtake Raw'!R:R,'Offtake Raw'!$C:$C,Hair!$D7,'Offtake Raw'!$D:$D,Hair!$E7)/1000000 -> 0.3364656 | Q7: =SUMIFS('Offtake Raw'!S:S,'Offtake Raw'!$C:$C,Hair!$D7,'Offtake Raw'!$D:$D,Hair!$E7)/1000000 -> 0.44455651 | R7: =SUMIFS('Offtake Raw'!T:T,'Offtake Raw'!$C:$C,Hair!$D7,'Offtake Raw'!$D:$D,Hair!$E7)/1000000 -> 0.64891845 | S7: =SUMIFS('Offtake Raw'!U:U,'Offtake Raw'!$C:$C,Hair!$D7,'Offtake Raw'!$D:$D,Hair!$E7)/1000000 -> 0.38463275 | T7: =SUMIFS('Offtake Raw'!V:V,'Offtake Raw'!$C:$C,Hair!$D7,'Offtake Raw'!$D:$D,Hair!$E7)/1000000 -> 0.40790886 | U7: =SUMIFS('Offtake Raw'!W:W,'Offtake Raw'!$C:$C,Hair!$D7,'Offtake Raw'!$D:$D,Hair!$E7)/1000000 -> 0.4088182 | V7: =SUMIFS('Offtake Raw'!X:X,'Offtake Raw'!$C:$C,Hair!$D7,'Offtake Raw'!$D:$D,Hair!$E7)/1000000 -> 0.45029509 | W7: =SUMIFS('Offtake Raw'!Y:Y,'Offtake Raw'!$C:$C,Hair!$D7,'Offtake Raw'!$D:$D,Hair!$E7)/1000000 -> 0.41537082 | X7: =SUMIFS('Offtake Raw'!Z:Z,'Offtake Raw'!$C:$C,Hair!$D7,'Offtake Raw'!$D:$D,Hair!$E7)/1000000 -> 0.82888856 | Y7: =SUMIFS('Offtake Raw'!AA:AA,'Offtake Raw'!$C:$C,Hair!$D7,'Offtake Raw'!$D:$D,Hair!$E7)/1000000 -> 0.85068402 | Z7: =SUMIFS('Offtake Raw'!AB:AB,'Offtake Raw'!$C:$C,Hair!$D7,'Offtake Raw'!$D:$D,Hair!$E7)/1000000 -> 0.36791353 | AA7: =SUMIFS('Offtake Raw'!AC:AC,'Offtake Raw'!$C:$C,Hair!$D7,'Offtake Raw'!$D:$D,Hair!$E7)/1000000 -> 0.47134485 | AB7: =SUMIFS('Offtake Raw'!AD:AD,'Offtake Raw'!$C:$C,Hair!$D7,'Offtake Raw'!$D:$D,Hair!$E7)/1000000 -> 0.73173035 | AC7: =SUMIFS('Offtake Raw'!AE:AE,'Offtake Raw'!$C:$C,Hair!$D7,'Offtake Raw'!$D:$D,Hair!$E7)/1000000 -> 0.82686716 | AD7: =SUMIFS('Offtake Raw'!AF:AF,'Offtake Raw'!$C:$C,Hair!$D7,'Offtake Raw'!$D:$D,Hair!$E7)/1000000 -> 0.54163944 | AE7: =SUMIFS('Offtake Raw'!AG:AG,'Offtake Raw'!$C:$C,Hair!$D7,'Offtake Raw'!$D:$D,Hair!$E7)/1000000 -> 0.39654747 | AF7: =SUMIFS('Offtake Raw'!AH:AH,'Offtake Raw'!$C:$C,Hair!$D7,'Offtake Raw'!$D:$D,Hair!$E7)/1000000 -> 0.46387828 | AG7: =SUMIFS('Offtake Raw'!AI:AI,'Offtake Raw'!$C:$C,Hair!$D7,'Offtake Raw'!$D:$D,Hair!$E7)/1000000 -> 0.67386844 | AH7: =AH13+AH19 -> 0.65 | AI7: =AI13+AI19 -> 0.85 | AK7: 0.35 | AL7: =AG7-AK7 -> 0.32386844 | AN7: =IFERROR(AG7/U7*100,"NA") -> 164.83328 | AO7: =IFERROR(SUM(X7:AG7)/SUM(L7:U7)*100,"NA") -> 149.56692 | AP7: =IFERROR(SUM(AD7:AG7)/SUM(R7:U7)*100,"NA") -> 112.19575 | AQ7: =IFERROR(SUM(X7:Z7)/SUM(L7:N7)*100,"NA") -> 193.60469 | AR7: =IFERROR(SUM(AA7:AC7)/SUM(O7:Q7)*100,"NA") -> 168.28104 | AS7: =IFERROR(SUM(AD7:AF7)/SUM(R7:T7)*100,"NA") -> 97.267016 | AT7: =IFERROR(SUM(AG7:AI7)/SUM(U7:W7)*100,"NA") -> 170.5685 | AU7: =IFERROR(SUM(X7:AC7)/SUM(L7:Q7)*100,"NA") -> 180.11106 | AV7: =IFERROR(SUM(AD7:AI7)/SUM(R7:W7)*100,"NA") -> 131.66447 | AW7: =IFERROR(SUM(X7:AI7)/SUM(L7:W7)*100,"NA") -> 153.68859
A8: Offtake | B8: Total | C8: Hair | D8: HNS | E8: Bullseye | F8: =SUMIFS('Offtake Raw'!H:H,'Offtake Raw'!$C:$C,Hair!$D8,'Offtake Raw'!$D:$D,Hair!$E8)/1000000 -> 0.153023 | G8: =SUMIFS('Offtake Raw'!I:I,'Offtake Raw'!$C:$C,Hair!$D8,'Offtake Raw'!$D:$D,Hair!$E8)/1000000 -> 0.2028296 | H8: =SUMIFS('Offtake Raw'!J:J,'Offtake Raw'!$C:$C,Hair!$D8,'Offtake Raw'!$D:$D,Hair!$E8)/1000000 -> 0.181289 | I8: =SUMIFS('Offtake Raw'!K:K,'Offtake Raw'!$C:$C,Hair!$D8,'Offtake Raw'!$D:$D,Hair!$E8)/1000000 -> 0.1315149 | J8: =SUMIFS('Offtake Raw'!L:L,'Offtake Raw'!$C:$C,Hair!$D8,'Offtake Raw'!$D:$D,Hair!$E8)/1000000 -> 0.1843839 | K8: =SUMIFS('Offtake Raw'!M:M,'Offtake Raw'!$C:$C,Hair!$D8,'Offtake Raw'!$D:$D,Hair!$E8)/1000000 -> 0.3014866 | L8: =SUMIFS('Offtake Raw'!N:N,'Offtake Raw'!$C:$C,Hair!$D8,'Offtake Raw'!$D:$D,Hair!$E8)/1000000 -> 0.1113329 | M8: =SUMIFS('Offtake Raw'!O:O,'Offtake Raw'!$C:$C,Hair!$D8,'Offtake Raw'!$D:$D,Hair!$E8)/1000000 -> 0.1381949 | N8: =SUMIFS('Offtake Raw'!P:P,'Offtake Raw'!$C:$C,Hair!$D8,'Offtake Raw'!$D:$D,Hair!$E8)/1000000 -> 0.170126 | O8: =SUMIFS('Offtake Raw'!Q:Q,'Offtake Raw'!$C:$C,Hair!$D8,'Offtake Raw'!$D:$D,Hair!$E8)/1000000 -> 0.075746 | P8: =SUMIFS('Offtake Raw'!R:R,'Offtake Raw'!$C:$C,Hair!$D8,'Offtake Raw'!$D:$D,Hair!$E8)/1000000 -> 0.16698 | Q8: =SUMIFS('Offtake Raw'!S:S,'Offtake Raw'!$C:$C,Hair!$D8,'Offtake Raw'!$D:$D,Hair!$E8)/1000000 -> 0.131406 | R8: =SUMIFS('Offtake Raw'!T:T,'Offtake Raw'!$C:$C,Hair!$D8,'Offtake Raw'!$D:$D,Hair!$E8)/1000000 -> 0.12584 | S8: =SUMIFS('Offtake Raw'!U:U,'Offtake Raw'!$C:$C,Hair!$D8,'Offtake Raw'!$D:$D,Hair!$E8)/1000000 -> 0.168916 | T8: =SUMIFS('Offtake Raw'!V:V,'Offtake Raw'!$C:$C,Hair!$D8,'Offtake Raw'!$D:$D,Hair!$E8)/1000000 -> 0.121726 | U8: =SUMIFS('Offtake Raw'!W:W,'Offtake Raw'!$C:$C,Hair!$D8,'Offtake Raw'!$D:$D,Hair!$E8)/1000000 -> 0.126566 | V8: =SUMIFS('Offtake Raw'!X:X,'Offtake Raw'!$C:$C,Hair!$D8,'Offtake Raw'!$D:$D,Hair!$E8)/1000000 -> 0.325006 | W8: =SUMIFS('Offtake Raw'!Y:Y,'Offtake Raw'!$C:$C,Hair!$D8,'Offtake Raw'!$D:$D,Hair!$E8)/1000000 -> 0.157058 | X8: =SUMIFS('Offtake Raw'!Z:Z,'Offtake Raw'!$C:$C,Hair!$D8,'Offtake Raw'!$D:$D,Hair!$E8)/1000000 -> 0.151492 | Y8: =SUMIFS('Offtake Raw'!AA:AA,'Offtake Raw'!$C:$C,Hair!$D8,'Offtake Raw'!$D:$D,Hair!$E8)/1000000 -> 0.132374 | Z8: =SUMIFS('Offtake Raw'!AB:AB,'Offtake Raw'!$C:$C,Hair!$D8,'Offtake Raw'!$D:$D,Hair!$E8)/1000000 -> 0.456654 | AA8: =SUMIFS('Offtake Raw'!AC:AC,'Offtake Raw'!$C:$C,Hair!$D8,'Offtake Raw'!$D:$D,Hair!$E8)/1000000 -> 0.237644 | AB8: =SUMIFS('Offtake Raw'!AD:AD,'Offtake Raw'!$C:$C,Hair!$D8,'Offtake Raw'!$D:$D,Hair!$E8)/1000000 -> 0.270798 | AC8: =SUMIFS('Offtake Raw'!AE:AE,'Offtake Raw'!$C:$C,Hair!$D8,'Offtake Raw'!$D:$D,Hair!$E8)/1000000 -> 0.230384 | AD8: =SUMIFS('Offtake Raw'!AF:AF,'Offtake Raw'!$C:$C,Hair!$D8,'Offtake Raw'!$D:$D,Hair!$E8)/1000000 -> 0.149556 | AE8: =SUMIFS('Offtake Raw'!AG:AG,'Offtake Raw'!$C:$C,Hair!$D8,'Offtake Raw'!$D:$D,Hair!$E8)/1000000 -> 0.168916 | AF8: =SUMIFS('Offtake Raw'!AH:AH,'Offtake Raw'!$C:$C,Hair!$D8,'Offtake Raw'!$D:$D,Hair!$E8)/1000000 -> 0.153428 | AG8: =SUMIFS('Offtake Raw'!AI:AI,'Offtake Raw'!$C:$C,Hair!$D8,'Offtake Raw'!$D:$D,Hair!$E8)/1000000 -> 0.23955311 | AH8: =AH14+AH20 -> 0.27 | AI8: =AI14+AI20 -> 0.27 | AK8: 0.12 | AL8: =AG8-AK8 -> 0.11955311 | AN8: =IFERROR(AG8/U8*100,"NA") -> 189.2713 | AO8: =IFERROR(SUM(X8:AG8)/SUM(L8:U8)*100,"NA") -> 163.87969 | AP8: =IFERROR(SUM(AD8:AG8)/SUM(R8:U8)*100,"NA") -> 131.01109 | AQ8: =IFERROR(SUM(X8:Z8)/SUM(L8:N8)*100,"NA") -> 176.45974 | AR8: =IFERROR(SUM(AA8:AC8)/SUM(O8:Q8)*100,"NA") -> 197.47736 | AS8: =IFERROR(SUM(AD8:AF8)/SUM(R8:T8)*100,"NA") -> 113.30622 | AT8: =IFERROR(SUM(AG8:AI8)/SUM(U8:W8)*100,"NA") -> 128.08325 | AU8: =IFERROR(SUM(X8:AC8)/SUM(L8:Q8)*100,"NA") -> 186.36589 | AV8: =IFERROR(SUM(AD8:AI8)/SUM(R8:W8)*100,"NA") -> 122.07965 | AW8: =IFERROR(SUM(X8:AI8)/SUM(L8:W8)*100,"NA") -> 150.13483
A9: Offtake | B9: Total | C9: Hair | D9: HNS | E9: Baymax | F9: 0 | G9: 0 | H9: 0 | I9: 0 | J9: 0 | K9: 0 | L9: 0 | M9: 0 | N9: 0 | O9: 0 | P9: 0 | Q9: 0 | R9: 0 | S9: 0 | T9: 0 | U9: 0 | V9: 0 | W9: 0 | X9: 0 | Y9: 0 | Z9: 0 | AA9: 0 | AB9: 0 | AC9: 0 | AD9: 0 | AE9: =SUMIFS('Offtake Raw'!AG:AG,'Offtake Raw'!$C:$C,Hair!$D9,'Offtake Raw'!$D:$D,Hair!$E9)/1000000 -> 0.2086656 | AF9: =SUMIFS('Offtake Raw'!AH:AH,'Offtake Raw'!$C:$C,Hair!$D9,'Offtake Raw'!$D:$D,Hair!$E9)/1000000 -> 0.171912 | AG9: =SUMIFS('Offtake Raw'!AI:AI,'Offtake Raw'!$C:$C,Hair!$D9,'Offtake Raw'!$D:$D,Hair!$E9)/1000000 -> 0.1419756 | AH9: =AH15+AH21 -> 0.15 | AI9: =AI15+AI21 -> 0.15 | AK9: 0.15 | AL9: =AG9-AK9 -> -0.0080244 | AN9: =IFERROR(AG9/U9*100,"NA") -> NA | AO9: =IFERROR(SUM(X9:AG9)/SUM(L9:U9)*100,"NA") -> NA | AP9: =IFERROR(SUM(AD9:AG9)/SUM(R9:U9)*100,"NA") -> NA | AQ9: =IFERROR(SUM(X9:Z9)/SUM(L9:N9)*100,"NA") -> NA | AR9: =IFERROR(SUM(AA9:AC9)/SUM(O9:Q9)*100,"NA") -> NA | AS9: =IFERROR(SUM(AD9:AF9)/SUM(R9:T9)*100,"NA") -> NA | AT9: =IFERROR(SUM(AG9:AI9)/SUM(U9:W9)*100,"NA") -> NA | AU9: =IFERROR(SUM(X9:AC9)/SUM(L9:Q9)*100,"NA") -> NA | AV9: =IFERROR(SUM(AD9:AI9)/SUM(R9:W9)*100,"NA") -> NA | AW9: =IFERROR(SUM(X9:AI9)/SUM(L9:W9)*100,"NA") -> NA
A10: Offtake | B10: Total | C10: Hair | D10: HNS | E10: Base | F10: =SUMIFS('Offtake Raw'!H:H,'Offtake Raw'!$C:$C,Hair!$D10,'Offtake Raw'!$D:$D,Hair!$E10)/1000000 -> 0.78234055 | G10: =SUMIFS('Offtake Raw'!I:I,'Offtake Raw'!$C:$C,Hair!$D10,'Offtake Raw'!$D:$D,Hair!$E10)/1000000 -> 1.0940766 | H10: =SUMIFS('Offtake Raw'!J:J,'Offtake Raw'!$C:$C,Hair!$D10,'Offtake Raw'!$D:$D,Hair!$E10)/1000000 -> 1.0197256 | I10: =SUMIFS('Offtake Raw'!K:K,'Offtake Raw'!$C:$C,Hair!$D10,'Offtake Raw'!$D:$D,Hair!$E10)/1000000 -> 0.79374586 | J10: =SUMIFS('Offtake Raw'!L:L,'Offtake Raw'!$C:$C,Hair!$D10,'Offtake Raw'!$D:$D,Hair!$E10)/1000000 -> 1.1190149 | K10: =SUMIFS('Offtake Raw'!M:M,'Offtake Raw'!$C:$C,Hair!$D10,'Offtake Raw'!$D:$D,Hair!$E10)/1000000 -> 1.3351709 | L10: =SUMIFS('Offtake Raw'!N:N,'Offtake Raw'!$C:$C,Hair!$D10,'Offtake Raw'!$D:$D,Hair!$E10)/1000000 -> 1.1507807 | M10: =SUMIFS('Offtake Raw'!O:O,'Offtake Raw'!$C:$C,Hair!$D10,'Offtake Raw'!$D:$D,Hair!$E10)/1000000 -> 1.0491227 | N10: =SUMIFS('Offtake Raw'!P:P,'Offtake Raw'!$C:$C,Hair!$D10,'Offtake Raw'!$D:$D,Hair!$E10)/1000000 -> 0.84085229 | O10: =SUMIFS('Offtake Raw'!Q:Q,'Offtake Raw'!$C:$C,Hair!$D10,'Offtake Raw'!$D:$D,Hair!$E10)/1000000 -> 1.0239015 | P10: =SUMIFS('Offtake Raw'!R:R,'Offtake Raw'!$C:$C,Hair!$D10,'Offtake Raw'!$D:$D,Hair!$E10)/1000000 -> 1.2224271 | Q10: =SUMIFS('Offtake Raw'!S:S,'Offtake Raw'!$C:$C,Hair!$D10,'Offtake Raw'!$D:$D,Hair!$E10)/1000000 -> 1.0861163 | R10: =SUMIFS('Offtake Raw'!T:T,'Offtake Raw'!$C:$C,Hair!$D10,'Offtake Raw'!$D:$D,Hair!$E10)/1000000 -> 0.95832251 | S10: =SUMIFS('Offtake Raw'!U:U,'Offtake Raw'!$C:$C,Hair!$D10,'Offtake Raw'!$D:$D,Hair!$E10)/1000000 -> 0.89140705 | T10: =SUMIFS('Offtake Raw'!V:V,'Offtake Raw'!$C:$C,Hair!$D10,'Offtake Raw'!$D:$D,Hair!$E10)/1000000 -> 0.76799943 | U10: =SUMIFS('Offtake Raw'!W:W,'Offtake Raw'!$C:$C,Hair!$D10,'Offtake Raw'!$D:$D,Hair!$E10)/1000000 -> 2.2065747 | V10: =SUMIFS('Offtake Raw'!X:X,'Offtake Raw'!$C:$C,Hair!$D10,'Offtake Raw'!$D:$D,Hair!$E10)/1000000 -> 2.3961105 | W10: =SUMIFS('Offtake Raw'!Y:Y,'Offtake Raw'!$C:$C,Hair!$D10,'Offtake Raw'!$D:$D,Hair!$E10)/1000000 -> 1.1322083 | X10: =SUMIFS('Offtake Raw'!Z:Z,'Offtake Raw'!$C:$C,Hair!$D10,'Offtake Raw'!$D:$D,Hair!$E10)/1000000 -> 1.2178078 | Y10: =SUMIFS('Offtake Raw'!AA:AA,'Offtake Raw'!$C:$C,Hair!$D10,'Offtake Raw'!$D:$D,Hair!$E10)/1000000 -> 0.92970875 | Z10: =SUMIFS('Offtake Raw'!AB:AB,'Offtake Raw'!$C:$C,Hair!$D10,'Offtake Raw'!$D:$D,Hair!$E10)/1000000 -> 0.77257652 | AA10: =SUMIFS('Offtake Raw'!AC:AC,'Offtake Raw'!$C:$C,Hair!$D10,'Offtake Raw'!$D:$D,Hair!$E10)/1000000 -> 1.1742547 | AB10: =SUMIFS('Offtake Raw'!AD:AD,'Offtake Raw'!$C:$C,Hair!$D10,'Offtake Raw'!$D:$D,Hair!$E10)/1000000 -> 1.4194614 | AC10: =SUMIFS('Offtake Raw'!AE:AE,'Offtake Raw'!$C:$C,Hair!$D10,'Offtake Raw'!$D:$D,Hair!$E10)/1000000 -> 1.2067664 | AD10: =SUMIFS('Offtake Raw'!AF:AF,'Offtake Raw'!$C:$C,Hair!$D10,'Offtake Raw'!$D:$D,Hair!$E10)/1000000 -> 1.0095541 | AE10: =SUMIFS('Offtake Raw'!AG:AG,'Offtake Raw'!$C:$C,Hair!$D10,'Offtake Raw'!$D:$D,Hair!$E10)/1000000 -> 0.96585441 | AF10: =SUMIFS('Offtake Raw'!AH:AH,'Offtake Raw'!$C:$C,Hair!$D10,'Offtake Raw'!$D:$D,Hair!$E10)/1000000 -> 0.74329502 | AG10: =SUMIFS('Offtake Raw'!AI:AI,'Offtake Raw'!$C:$C,Hair!$D10,'Offtake Raw'!$D:$D,Hair!$E10)/1000000 -> 1.0227545 | AH10: =AH16+AH22 -> 1 | AI10: =AI16+AI22 -> 1.2 | AK10: 1 | AL10: =AG10-AK10 -> 0.022754451 | AN10: =IFERROR(AG10/U10*100,"NA") -> 46.35032 | AO10: =IFERROR(SUM(X10:AG10)/SUM(L10:U10)*100,"NA") -> 93.431833 | AP10: =IFERROR(SUM(AD10:AG10)/SUM(R10:U10)*100,"NA") -> 77.554363 | AQ10: =IFERROR(SUM(X10:Z10)/SUM(L10:N10)*100,"NA") -> 96.031818 | AR10: =IFERROR(SUM(AA10:AC10)/SUM(O10:Q10)*100,"NA") -> 114.04487 | AS10: =IFERROR(SUM(AD10:AF10)/SUM(R10:T10)*100,"NA") -> 103.85734 | AT10: =IFERROR(SUM(AG10:AI10)/SUM(U10:W10)*100,"NA") -> 56.19554 | AU10: =IFERROR(SUM(X10:AC10)/SUM(L10:Q10)*100,"NA") -> 105.45056 | AV10: =IFERROR(SUM(AD10:AI10)/SUM(R10:W10)*100,"NA") -> 71.132844 | AW10: =IFERROR(SUM(X10:AI10)/SUM(L10:W10)*100,"NA") -> 85.985235
A11: Offtake | B11: Total | C11: Hair | D11: HNS | E11: Core+ | F11: =SUM(F7,F8,F9) -> 0.3737612 | G11: =SUM(G7,G8,G9) -> 0.4263014 | H11: =SUM(H7,H8,H9) -> 0.4100002 | I11: =SUM(I7,I8,I9) -> 0.3609095 | J11: =SUM(J7,J8,J9) -> 0.3793807 | K11: =SUM(K7,K8,K9) -> 0.4898772 | L11: =SUM(L7,L8,L9) -> 0.3349253 | M11: =SUM(M7,M8,M9) -> 0.6116397 | ... AI11: =SUM(AI7,AI8,AI9) -> 1.27 | AK11: 0.62 | AL11: =AG11-AK11 -> 0.43539715 | AN11: =IFERROR(AG11/U11*100,"NA") -> 197.12893 | AO11: =IFERROR(SUM(X11:AG11)/SUM(L11:U11)*100,"NA") -> 162.66355 | AP11: =IFERROR(SUM(AD11:AG11)/SUM(R11:U11)*100,"NA") -> 138.29873 | AQ11: =IFERROR(SUM(X11:Z11)/SUM(L11:N11)*100,"NA") -> 188.73407 | AR11: =IFERROR(SUM(AA11:AC11)/SUM(O11:Q11)*100,"NA") -> 175.1927 | AS11: =IFERROR(SUM(AD11:AF11)/SUM(R11:T11)*100,"NA") -> 121.34624 | AT11: =IFERROR(SUM(AG11:AI11)/SUM(U11:W11)*100,"NA") -> 180.30756 | AU11: =IFERROR(SUM(X11:AC11)/SUM(L11:Q11)*100,"NA") -> 181.73486 | AV11: =IFERROR(SUM(AD11:AI11)/SUM(R11:W11)*100,"NA") -> 151.02526 | AW11: =IFERROR(SUM(X11:AI11)/SUM(L11:W11)*100,"NA") -> 164.83654
A12: Offtake | B12: Normal | C12: Hair | D12: HNS | E12: Total | F12: =SUM(F17,F16) -> 1.47 | G12: =SUM(G17,G16) -> 1.47 | H12: =SUM(H17,H16) -> 1.47 | I12: =SUM(I17,I16) -> 1.47 | J12: =SUM(J17,J16) -> 1.47 | K12: =SUM(K17,K16) -> 1.47 | L12: =SUM(L17,L16) -> 1.47 | M12: =SUM(M17,M16) -> 1.47 | ... AI12: =SUM(AI17,AI16) -> 1.47
A13: Offtake | B13: Normal | C13: Hair | D13: HNS | E13: Ironman | F13: 0.35 | G13: 0.35 | H13: 0.35 | I13: 0.35 | J13: 0.35 | K13: 0.35 | L13: 0.35 | M13: 0.35 | N13: 0.35 | O13: 0.35 | P13: 0.35 | Q13: 0.35 | R13: 0.35 | S13: 0.35 | T13: 0.35 | U13: 0.35 | V13: 0.35 | W13: 0.35 | X13: 0.35 | Y13: 0.35 | Z13: 0.35 | AA13: 0.35 | AB13: 0.35 | AC13: 0.35 | AD13: 0.35 | AE13: 0.35 | AF13: 0.35 | AG13: 0.35 | AH13: 0.35 | AI13: 0.35
A14: Offtake | B14: Normal | C14: Hair | D14: HNS | E14: Bullseye | F14: 0.12 | G14: 0.12 | H14: 0.12 | I14: 0.12 | J14: 0.12 | K14: 0.12 | L14: 0.12 | M14: 0.12 | N14: 0.12 | O14: 0.12 | P14: 0.12 | Q14: 0.12 | R14: 0.12 | S14: 0.12 | T14: 0.12 | U14: 0.12 | V14: 0.12 | W14: 0.12 | X14: 0.12 | Y14: 0.12 | Z14: 0.12 | AA14: 0.12 | AB14: 0.12 | AC14: 0.12 | AD14: 0.12 | AE14: 0.12 | AF14: 0.12 | AG14: 0.12 | AH14: 0.12 | AI14: 0.12
A15: Offtake | B15: Normal | C15: Hair | D15: HNS | E15: Baymax | F15: 0 | G15: 0 | H15: 0 | I15: 0 | J15: 0 | K15: 0 | L15: 0 | M15: 0 | N15: 0 | O15: 0 | P15: 0 | Q15: 0 | R15: 0 | S15: 0 | T15: 0 | U15: 0 | V15: 0 | W15: 0 | X15: 0 | Y15: 0 | Z15: 0 | AA15: 0 | AB15: 0 | AC15: 0 | AD15: 0 | AE15: 0 | AF15: 0 | AG15: 0 | AH15: 0 | AI15: 0
A16: Offtake | B16: Normal | C16: Hair | D16: HNS | E16: Base | F16: 1 | G16: 1 | H16: 1 | I16: 1 | J16: 1 | K16: 1 | L16: 1 | M16: 1 | N16: 1 | O16: 1 | P16: 1 | Q16: 1 | R16: 1 | S16: 1 | T16: 1 | U16: 1 | V16: 1 | W16: 1 | X16: 1 | Y16: 1 | Z16: 1 | AA16: 1 | AB16: 1 | AC16: 1 | AD16: 1 | AE16: 1 | AF16: 1 | AG16: 1 | AH16: 1 | AI16: 1
A17: Offtake | B17: Normal | C17: Hair | D17: HNS | E17: Core+ | F17: =SUM(F13,F14,F15) -> 0.47 | G17: =SUM(G13,G14,G15) -> 0.47 | H17: =SUM(H13,H14,H15) -> 0.47 | I17: =SUM(I13,I14,I15) -> 0.47 | J17: =SUM(J13,J14,J15) -> 0.47 | K17: =SUM(K13,K14,K15) -> 0.47 | L17: =SUM(L13,L14,L15) -> 0.47 | M17: =SUM(M13,M14,M15) -> 0.47 | ... AI17: =SUM(AI13,AI14,AI15) -> 0.47
A18: Offtake | B18: Uplift | C18: Hair | D18: HNS | E18: Total | AD18: =SUM(AD23,AD22) -> 0 | AE18: =SUM(AE23,AE22) -> 0.1 | AF18: =SUM(AF23,AF22) -> 0.4 | AG18: =SUM(AG23,AG22) -> 0.15 | AH18: =SUM(AH23,AH22) -> 0.6 | AI18: =SUM(AI23,AI22) -> 1
A19: Offtake | B19: Uplift | C19: Hair | D19: HNS | E19: Ironman | AH19: 0.3 | AI19: 0.5
A20: Offtake | B20: Uplift | C20: Hair | D20: HNS | E20: Bullseye | AH20: 0.15 | AI20: 0.15
A21: Offtake | B21: Uplift | C21: Hair | D21: HNS | E21: Baymax | AE21: 0.1 | AF21: 0.1 | AG21: 0.15 | AH21: 0.15 | AI21: 0.15
A22: Offtake | B22: Uplift | C22: Hair | D22: HNS | E22: Base | AF22: 0.3 | AI22: 0.2
A23: Offtake | B23: Uplift | C23: Hair | D23: HNS | E23: Core+ | AD23: =SUM(AD19,AD20,AD21) -> 0 | AE23: =SUM(AE19,AE20,AE21) -> 0.1 | AF23: =SUM(AF19,AF20,AF21) -> 0.1 | AG23: =SUM(AG19,AG20,AG21) -> 0.15 | AH23: =SUM(AH19,AH20,AH21) -> 0.6 | AI23: =SUM(AI19,AI20,AI21) -> 0.8
